Workbook

Sheet Summary
A1: EHT ITR Summary
A4: Panel | B4: Total | C4: Traces | D4: Power | E4: RTDs | F4: RTD Cables | G4: ITR | H4: Visual | I4: Rec. Megger | J4: Pre-Insul Megger | K4: Post-Insul Megger | L4: Cable IR | M4: Cable Cont. | N4: RTD Pre | O4: RTD Post | P4: Dated | Q4: Complete
A5: 29103-HTP-102 | B5: =COUNTA('29103-HTP-102'!$B$5:$B$148) -> 144 | C5: =COUNTIF('29103-HTP-102'!$A$5:$A$148,"EHT Trace") -> 56 | D5: =COUNTIF('29103-HTP-102'!$A$5:$A$148,"Power Cable") -> 38 | E5: =COUNTIF('29103-HTP-102'!$A$5:$A$148,"RTD") -> 22 | F5: =COUNTIF('29103-HTP-102'!$A$5:$A$148,"RTD Cable") -> 28 | G5: =COUNTIF('29103-HTP-102'!$I$5:$I$148,"YES")&" / "&(COUNTA('29103-HTP-102'!$I$5:$I$148)-COUNTIF('29103-HTP-102'!$I$5:$I$148,"N/A")) -> 144 / 144 | H5: =COUNTIF('29103-HTP-102'!$J$5:$J$148,"YES")&" / "&(COUNTA('29103-HTP-102'!$J$5:$J$148)-COUNTIF('29103-HTP-102'!$J$5:$J$148,"N/A")) -> 0 / 144 | I5: =COUNTIF('29103-HTP-102'!$K$5:$K$148,"YES")&" / "&(COUNTA('29103-HTP-102'!$K$5:$K$148)-COUNTIF('29103-HTP-102'!$K$5:$K$148,"N/A")) -> 10 / 56 | J5: =COUNTIF('29103-HTP-102'!$L$5:$L$148,"YES")&" / "&(COUNTA('29103-HTP-102'!$L$5:$L$148)-COUNTIF('29103-HTP-102'!$L$5:$L$148,"N/A")) -> 0 / 56 | K5: =COUNTIF('29103-HTP-102'!$M$5:$M$148,"YES")&" / "&(COUNTA('29103-HTP-102'!$M$5:$M$148)-COUNTIF('29103-HTP-102'!$M$5:$M$148,"N/A")) -> 0 / 56 | L5: =COUNTIF('29103-HTP-102'!$N$5:$N$148,"YES")&" / "&(COUNTA('29103-HTP-102'!$N$5:$N$148)-COUNTIF('29103-HTP-102'!$N$5:$N$148,"N/A")) -> 0 / 38 | M5: =COUNTIF('29103-HTP-102'!$O$5:$O$148,"YES")&" / "&(COUNTA('29103-HTP-102'!$O$5:$O$148)-COUNTIF('29103-HTP-102'!$O$5:$O$148,"N/A")) -> 0 / 66 | N5: =COUNTIF('29103-HTP-102'!$P$5:$P$148,"YES")&" / "&(COUNTA('29103-HTP-102'!$P$5:$P$148)-COUNTIF('29103-HTP-102'!$P$5:$P$148,"N/A")) -> 0 / 22 | O5: =COUNTIF('29103-HTP-102'!$Q$5:$Q$148,"YES")&" / "&(COUNTA('29103-HTP-102'!$Q$5:$Q$148)-COUNTIF('29103-HTP-102'!$Q$5:$Q$148,"N/A")) -> 0 / 22 | P5: =COUNTIF('29103-HTP-102'!$R$5:$R$148,"YES")&" / "&(COUNTA('29103-HTP-102'!$R$5:$R$148)-COUNTIF('29103-HTP-102'!$R$5:$R$148,"N/A")) -> 0 / 144 | Q5: =COUNTIF('29103-HTP-102'!$S$5:$S$148,"YES")&" / "&(COUNTA('29103-HTP-102'!$S$5:$S$148)-COUNTIF('29103-HTP-102'!$S$5:$S$148,"N/A")) -> 0 / 144
A6: 29103-HTP-100 | B6: =COUNTA('29103-HTP-100'!$B$5:$B$64) -> 60 | C6: =COUNTIF('29103-HTP-100'!$A$5:$A$64,"EHT Trace") -> 21 | D6: =COUNTIF('29103-HTP-100'!$A$5:$A$64,"Power Cable") -> 15 | E6: =COUNTIF('29103-HTP-100'!$A$5:$A$64,"RTD") -> 12 | F6: =COUNTIF('29103-HTP-100'!$A$5:$A$64,"RTD Cable") -> 12 | G6: =COUNTIF('29103-HTP-100'!$I$5:$I$64,"YES")&" / "&(COUNTA('29103-HTP-100'!$I$5:$I$64)-COUNTIF('29103-HTP-100'!$I$5:$I$64,"N/A")) -> 60 / 60 | H6: =COUNTIF('29103-HTP-100'!$J$5:$J$64,"YES")&" / "&(COUNTA('29103-HTP-100'!$J$5:$J$64)-COUNTIF('29103-HTP-100'!$J$5:$J$64,"N/A")) -> 2 / 60 | I6: =COUNTIF('29103-HTP-100'!$K$5:$K$64,"YES")&" / "&(COUNTA('29103-HTP-100'!$K$5:$K$64)-COUNTIF('29103-HTP-100'!$K$5:$K$64,"N/A")) -> 2 / 21 | J6: =COUNTIF('29103-HTP-100'!$L$5:$L$64,"YES")&" / "&(COUNTA('29103-HTP-100'!$L$5:$L$64)-COUNTIF('29103-HTP-100'!$L$5:$L$64,"N/A")) -> 2 / 21 | K6: =COUNTIF('29103-HTP-100'!$M$5:$M$64,"YES")&" / "&(COUNTA('29103-HTP-100'!$M$5:$M$64)-COUNTIF('29103-HTP-100'!$M$5:$M$64,"N/A")) -> 0 / 21 | L6: =COUNTIF('29103-HTP-100'!$N$5:$N$64,"YES")&" / "&(COUNTA('29103-HTP-100'!$N$5:$N$64)-COUNTIF('29103-HTP-100'!$N$5:$N$64,"N/A")) -> 0 / 15 | M6: =COUNTIF('29103-HTP-100'!$O$5:$O$64,"YES")&" / "&(COUNTA('29103-HTP-100'!$O$5:$O$64)-COUNTIF('29103-HTP-100'!$O$5:$O$64,"N/A")) -> 0 / 27 | N6: =COUNTIF('29103-HTP-100'!$P$5:$P$64,"YES")&" / "&(COUNTA('29103-HTP-100'!$P$5:$P$64)-COUNTIF('29103-HTP-100'!$P$5:$P$64,"N/A")) -> 0 / 12 | O6: =COUNTIF('29103-HTP-100'!$Q$5:$Q$64,"YES")&" / "&(COUNTA('29103-HTP-100'!$Q$5:$Q$64)-COUNTIF('29103-HTP-100'!$Q$5:$Q$64,"N/A")) -> 0 / 12 | P6: =COUNTIF('29103-HTP-100'!$R$5:$R$64,"YES")&" / "&(COUNTA('29103-HTP-100'!$R$5:$R$64)-COUNTIF('29103-HTP-100'!$R$5:$R$64,"N/A")) -> 4 / 60 | Q6: =COUNTIF('29103-HTP-100'!$S$5:$S$64,"YES")&" / "&(COUNTA('29103-HTP-100'!$S$5:$S$64)-COUNTIF('29103-HTP-100'!$S$5:$S$64,"N/A")) -> 0 / 60
A7: 29103-HTP-101 | B7: =COUNTA('29103-HTP-101'!$B$5:$B$79) -> 75 | C7: =COUNTIF('29103-HTP-101'!$A$5:$A$79,"EHT Trace") -> 28 | D7: =COUNTIF('29103-HTP-101'!$A$5:$A$79,"Power Cable") -> 19 | E7: =COUNTIF('29103-HTP-101'!$A$5:$A$79,"RTD") -> 13 | F7: =COUNTIF('29103-HTP-101'!$A$5:$A$79,"RTD Cable") -> 15 | G7: =COUNTIF('29103-HTP-101'!$I$5:$I$79,"YES")&" / "&(COUNTA('29103-HTP-101'!$I$5:$I$79)-COUNTIF('29103-HTP-101'!$I$5:$I$79,"N/A")) -> 75 / 75 | H7: =COUNTIF('29103-HTP-101'!$J$5:$J$79,"YES")&" / "&(COUNTA('29103-HTP-101'!$J$5:$J$79)-COUNTIF('29103-HTP-101'!$J$5:$J$79,"N/A")) -> 0 / 75 | I7: =COUNTIF('29103-HTP-101'!$K$5:$K$79,"YES")&" / "&(COUNTA('29103-HTP-101'!$K$5:$K$79)-COUNTIF('29103-HTP-101'!$K$5:$K$79,"N/A")) -> 8 / 28 | J7: =COUNTIF('29103-HTP-101'!$L$5:$L$79,"YES")&" / "&(COUNTA('29103-HTP-101'!$L$5:$L$79)-COUNTIF('29103-HTP-101'!$L$5:$L$79,"N/A")) -> 2 / 28 | K7: =COUNTIF('29103-HTP-101'!$M$5:$M$79,"YES")&" / "&(COUNTA('29103-HTP-101'!$M$5:$M$79)-COUNTIF('29103-HTP-101'!$M$5:$M$79,"N/A")) -> 0 / 28 | L7: =COUNTIF('29103-HTP-101'!$N$5:$N$79,"YES")&" / "&(COUNTA('29103-HTP-101'!$N$5:$N$79)-COUNTIF('29103-HTP-101'!$N$5:$N$79,"N/A")) -> 0 / 19 | M7: =COUNTIF('29103-HTP-101'!$O$5:$O$79,"YES")&" / "&(COUNTA('29103-HTP-101'!$O$5:$O$79)-COUNTIF('29103-HTP-101'!$O$5:$O$79,"N/A")) -> 0 / 34 | N7: =COUNTIF('29103-HTP-101'!$P$5:$P$79,"YES")&" / "&(COUNTA('29103-HTP-101'!$P$5:$P$79)-COUNTIF('29103-HTP-101'!$P$5:$P$79,"N/A")) -> 0 / 13 | O7: =COUNTIF('29103-HTP-101'!$Q$5:$Q$79,"YES")&" / "&(COUNTA('29103-HTP-101'!$Q$5:$Q$79)-COUNTIF('29103-HTP-101'!$Q$5:$Q$79,"N/A")) -> 0 / 13 | P7: =COUNTIF('29103-HTP-101'!$R$5:$R$79,"YES")&" / "&(COUNTA('29103-HTP-101'!$R$5:$R$79)-COUNTIF('29103-HTP-101'!$R$5:$R$79,"N/A")) -> 4 / 75 | Q7: =COUNTIF('29103-HTP-101'!$S$5:$S$79,"YES")&" / "&(COUNTA('29103-HTP-101'!$S$5:$S$79)-COUNTIF('29103-HTP-101'!$S$5:$S$79,"N/A")) -> 0 / 75
A8: 29103-HTP-004 | B8: =COUNTA('29103-HTP-004'!$B$5:$B$266) -> 262 | C8: =COUNTIF('29103-HTP-004'!$A$5:$A$266,"EHT Trace") -> 116 | D8: =COUNTIF('29103-HTP-004'!$A$5:$A$266,"Power Cable") -> 48 | E8: =COUNTIF('29103-HTP-004'!$A$5:$A$266,"RTD") -> 47 | F8: =COUNTIF('29103-HTP-004'!$A$5:$A$266,"RTD Cable") -> 51 | G8: =COUNTIF('29103-HTP-004'!$I$5:$I$266,"YES")&" / "&(COUNTA('29103-HTP-004'!$I$5:$I$266)-COUNTIF('29103-HTP-004'!$I$5:$I$266,"N/A")) -> 262 / 262 | H8: =COUNTIF('29103-HTP-004'!$J$5:$J$266,"YES")&" / "&(COUNTA('29103-HTP-004'!$J$5:$J$266)-COUNTIF('29103-HTP-004'!$J$5:$J$266,"N/A")) -> 0 / 262 | I8: =COUNTIF('29103-HTP-004'!$K$5:$K$266,"YES")&" / "&(COUNTA('29103-HTP-004'!$K$5:$K$266)-COUNTIF('29103-HTP-004'!$K$5:$K$266,"N/A")) -> 45 / 116 | J8: =COUNTIF('29103-HTP-004'!$L$5:$L$266,"YES")&" / "&(COUNTA('29103-HTP-004'!$L$5:$L$266)-COUNTIF('29103-HTP-004'!$L$5:$L$266,"N/A")) -> 0 / 116 | K8: =COUNTIF('29103-HTP-004'!$M$5:$M$266,"YES")&" / "&(COUNTA('29103-HTP-004'!$M$5:$M$266)-COUNTIF('29103-HTP-004'!$M$5:$M$266,"N/A")) -> 0 / 116 | L8: =COUNTIF('29103-HTP-004'!$N$5:$N$266,"YES")&" / "&(COUNTA('29103-HTP-004'!$N$5:$N$266)-COUNTIF('29103-HTP-004'!$N$5:$N$266,"N/A")) -> 0 / 48 | M8: =COUNTIF('29103-HTP-004'!$O$5:$O$266,"YES")&" / "&(COUNTA('29103-HTP-004'!$O$5:$O$266)-COUNTIF('29103-HTP-004'!$O$5:$O$266,"N/A")) -> 0 / 99 | N8: =COUNTIF('29103-HTP-004'!$P$5:$P$266,"YES")&" / "&(COUNTA('29103-HTP-004'!$P$5:$P$266)-COUNTIF('29103-HTP-004'!$P$5:$P$266,"N/A")) -> 0 / 47 | O8: =COUNTIF('29103-HTP-004'!$Q$5:$Q$266,"YES")&" / "&(COUNTA('29103-HTP-004'!$Q$5:$Q$266)-COUNTIF('29103-HTP-004'!$Q$5:$Q$266,"N/A")) -> 0 / 47 | P8: =COUNTIF('29103-HTP-004'!$R$5:$R$266,"YES")&" / "&(COUNTA('29103-HTP-004'!$R$5:$R$266)-COUNTIF('29103-HTP-004'!$R$5:$R$266,"N/A")) -> 0 / 262 | Q8: =COUNTIF('29103-HTP-004'!$S$5:$S$266,"YES")&" / "&(COUNTA('29103-HTP-004'!$S$5:$S$266)-COUNTIF('29103-HTP-004'!$S$5:$S$266,"N/A")) -> 0 / 262
A9: 29103-HTP-005 | B9: =COUNTA('29103-HTP-005'!$B$5:$B$252) -> 248 | C9: =COUNTIF('29103-HTP-005'!$A$5:$A$252,"EHT Trace") -> 108 | D9: =COUNTIF('29103-HTP-005'!$A$5:$A$252,"Power Cable") -> 47 | E9: =COUNTIF('29103-HTP-005'!$A$5:$A$252,"RTD") -> 45 | F9: =COUNTIF('29103-HTP-005'!$A$5:$A$252,"RTD Cable") -> 48 | G9: =COUNTIF('29103-HTP-005'!$I$5:$I$252,"YES")&" / "&(COUNTA('29103-HTP-005'!$I$5:$I$252)-COUNTIF('29103-HTP-005'!$I$5:$I$252,"N/A")) -> 248 / 248 | H9: =COUNTIF('29103-HTP-005'!$J$5:$J$252,"YES")&" / "&(COUNTA('29103-HTP-005'!$J$5:$J$252)-COUNTIF('29103-HTP-005'!$J$5:$J$252,"N/A")) -> 0 / 248 | I9: =COUNTIF('29103-HTP-005'!$K$5:$K$252,"YES")&" / "&(COUNTA('29103-HTP-005'!$K$5:$K$252)-COUNTIF('29103-HTP-005'!$K$5:$K$252,"N/A")) -> 28 / 108 | J9: =COUNTIF('29103-HTP-005'!$L$5:$L$252,"YES")&" / "&(COUNTA('29103-HTP-005'!$L$5:$L$252)-COUNTIF('29103-HTP-005'!$L$5:$L$252,"N/A")) -> 0 / 108 | K9: =COUNTIF('29103-HTP-005'!$M$5:$M$252,"YES")&" / "&(COUNTA('29103-HTP-005'!$M$5:$M$252)-COUNTIF('29103-HTP-005'!$M$5:$M$252,"N/A")) -> 0 / 108 | L9: =COUNTIF('29103-HTP-005'!$N$5:$N$252,"YES")&" / "&(COUNTA('29103-HTP-005'!$N$5:$N$252)-COUNTIF('29103-HTP-005'!$N$5:$N$252,"N/A")) -> 0 / 47 | M9: =COUNTIF('29103-HTP-005'!$O$5:$O$252,"YES")&" / "&(COUNTA('29103-HTP-005'!$O$5:$O$252)-COUNTIF('29103-HTP-005'!$O$5:$O$252,"N/A")) -> 0 / 95 | N9: =COUNTIF('29103-HTP-005'!$P$5:$P$252,"YES")&" / "&(COUNTA('29103-HTP-005'!$P$5:$P$252)-COUNTIF('29103-HTP-005'!$P$5:$P$252,"N/A")) -> 0 / 45 | O9: =COUNTIF('29103-HTP-005'!$Q$5:$Q$252,"YES")&" / "&(COUNTA('29103-HTP-005'!$Q$5:$Q$252)-COUNTIF('29103-HTP-005'!$Q$5:$Q$252,"N/A")) -> 0 / 45 | P9: =COUNTIF('29103-HTP-005'!$R$5:$R$252,"YES")&" / "&(COUNTA('29103-HTP-005'!$R$5:$R$252)-COUNTIF('29103-HTP-005'!$R$5:$R$252,"N/A")) -> 0 / 248 | Q9: =COUNTIF('29103-HTP-005'!$S$5:$S$252,"YES")&" / "&(COUNTA('29103-HTP-005'!$S$5:$S$252)-COUNTIF('29103-HTP-005'!$S$5:$S$252,"N/A")) -> 0 / 248
A10: 29103-HTP-003 | B10: =COUNTA('29103-HTP-003'!$B$5:$B$273) -> 269 | C10: =COUNTIF('29103-HTP-003'!$A$5:$A$273,"EHT Trace") -> 118 | D10: =COUNTIF('29103-HTP-003'!$A$5:$A$273,"Power Cable") -> 49 | E10: =COUNTIF('29103-HTP-003'!$A$5:$A$273,"RTD") -> 49 | F10: =COUNTIF('29103-HTP-003'!$A$5:$A$273,"RTD Cable") -> 53 | G10: =COUNTIF('29103-HTP-003'!$I$5:$I$273,"YES")&" / "&(COUNTA('29103-HTP-003'!$I$5:$I$273)-COUNTIF('29103-HTP-003'!$I$5:$I$273,"N/A")) -> 269 / 269 | H10: =COUNTIF('29103-HTP-003'!$J$5:$J$273,"YES")&" / "&(COUNTA('29103-HTP-003'!$J$5:$J$273)-COUNTIF('29103-HTP-003'!$J$5:$J$273,"N/A")) -> 9 / 269 | I10: =COUNTIF('29103-HTP-003'!$K$5:$K$273,"YES")&" / "&(COUNTA('29103-HTP-003'!$K$5:$K$273)-COUNTIF('29103-HTP-003'!$K$5:$K$273,"N/A")) -> 32 / 118 | J10: =COUNTIF('29103-HTP-003'!$L$5:$L$273,"YES")&" / "&(COUNTA('29103-HTP-003'!$L$5:$L$273)-COUNTIF('29103-HTP-003'!$L$5:$L$273,"N/A")) -> 3 / 118 | K10: =COUNTIF('29103-HTP-003'!$M$5:$M$273,"YES")&" / "&(COUNTA('29103-HTP-003'!$M$5:$M$273)-COUNTIF('29103-HTP-003'!$M$5:$M$273,"N/A")) -> 0 / 118 | L10: =COUNTIF('29103-HTP-003'!$N$5:$N$273,"YES")&" / "&(COUNTA('29103-HTP-003'!$N$5:$N$273)-COUNTIF('29103-HTP-003'!$N$5:$N$273,"N/A")) -> 0 / 49 | M10: =COUNTIF('29103-HTP-003'!$O$5:$O$273,"YES")&" / "&(COUNTA('29103-HTP-003'!$O$5:$O$273)-COUNTIF('29103-HTP-003'!$O$5:$O$273,"N/A")) -> 0 / 102 | N10: =COUNTIF('29103-HTP-003'!$P$5:$P$273,"YES")&" / "&(COUNTA('29103-HTP-003'!$P$5:$P$273)-COUNTIF('29103-HTP-003'!$P$5:$P$273,"N/A")) -> 0 / 49 | O10: =COUNTIF('29103-HTP-003'!$Q$5:$Q$273,"YES")&" / "&(COUNTA('29103-HTP-003'!$Q$5:$Q$273)-COUNTIF('29103-HTP-003'!$Q$5:$Q$273,"N/A")) -> 0 / 49 | P10: =COUNTIF('29103-HTP-003'!$R$5:$R$273,"YES")&" / "&(COUNTA('29103-HTP-003'!$R$5:$R$273)-COUNTIF('29103-HTP-003'!$R$5:$R$273,"N/A")) -> 9 / 269 | Q10: =COUNTIF('29103-HTP-003'!$S$5:$S$273,"YES")&" / "&(COUNTA('29103-HTP-003'!$S$5:$S$273)-COUNTIF('29103-HTP-003'!$S$5:$S$273,"N/A")) -> 0 / 269
A11: 29103-HTP-002 | B11: =COUNTA('29103-HTP-002'!$B$5:$B$246) -> 242 | C11: =COUNTIF('29103-HTP-002'!$A$5:$A$246,"EHT Trace") -> 106 | D11: =COUNTIF('29103-HTP-002'!$A$5:$A$246,"Power Cable") -> 46 | E11: =COUNTIF('29103-HTP-002'!$A$5:$A$246,"RTD") -> 44 | F11: =COUNTIF('29103-HTP-002'!$A$5:$A$246,"RTD Cable") -> 46 | G11: =COUNTIF('29103-HTP-002'!$I$5:$I$246,"YES")&" / "&(COUNTA('29103-HTP-002'!$I$5:$I$246)-COUNTIF('29103-HTP-002'!$I$5:$I$246,"N/A")) -> 242 / 242 | H11: =COUNTIF('29103-HTP-002'!$J$5:$J$246,"YES")&" / "&(COUNTA('29103-HTP-002'!$J$5:$J$246)-COUNTIF('29103-HTP-002'!$J$5:$J$246,"N/A")) -> 59 / 242 | I11: =COUNTIF('29103-HTP-002'!$K$5:$K$246,"YES")&" / "&(COUNTA('29103-HTP-002'!$K$5:$K$246)-COUNTIF('29103-HTP-002'!$K$5:$K$246,"N/A")) -> 19 / 106 | J11: =COUNTIF('29103-HTP-002'!$L$5:$L$246,"YES")&" / "&(COUNTA('29103-HTP-002'!$L$5:$L$246)-COUNTIF('29103-HTP-002'!$L$5:$L$246,"N/A")) -> 3 / 106 | K11: =COUNTIF('29103-HTP-002'!$M$5:$M$246,"YES")&" / "&(COUNTA('29103-HTP-002'!$M$5:$M$246)-COUNTIF('29103-HTP-002'!$M$5:$M$246,"N/A")) -> 0 / 106 | L11: =COUNTIF('29103-HTP-002'!$N$5:$N$246,"YES")&" / "&(COUNTA('29103-HTP-002'!$N$5:$N$246)-COUNTIF('29103-HTP-002'!$N$5:$N$246,"N/A")) -> 10 / 46 | M11: =COUNTIF('29103-HTP-002'!$O$5:$O$246,"YES")&" / "&(COUNTA('29103-HTP-002'!$O$5:$O$246)-COUNTIF('29103-HTP-002'!$O$5:$O$246,"N/A")) -> 33 / 92 | N11: =COUNTIF('29103-HTP-002'!$P$5:$P$246,"YES")&" / "&(COUNTA('29103-HTP-002'!$P$5:$P$246)-COUNTIF('29103-HTP-002'!$P$5:$P$246,"N/A")) -> 1 / 44 | O11: =COUNTIF('29103-HTP-002'!$Q$5:$Q$246,"YES")&" / "&(COUNTA('29103-HTP-002'!$Q$5:$Q$246)-COUNTIF('29103-HTP-002'!$Q$5:$Q$246,"N/A")) -> 23 / 44 | P11: =COUNTIF('29103-HTP-002'!$R$5:$R$246,"YES")&" / "&(COUNTA('29103-HTP-002'!$R$5:$R$246)-COUNTIF('29103-HTP-002'!$R$5:$R$246,"N/A")) -> 62 / 242 | Q11: =COUNTIF('29103-HTP-002'!$S$5:$S$246,"YES")&" / "&(COUNTA('29103-HTP-002'!$S$5:$S$246)-COUNTIF('29103-HTP-002'!$S$5:$S$246,"N/A")) -> 33 / 242
A12: 29151-HTP-001 | B12: =COUNTA('29151-HTP-001'!$B$5:$B$39) -> 35 | C12: =COUNTIF('29151-HTP-001'!$A$5:$A$39,"EHT Trace") -> 18 | D12: =COUNTIF('29151-HTP-001'!$A$5:$A$39,"Power Cable") -> 17 | E12: =COUNTIF('29151-HTP-001'!$A$5:$A$39,"RTD") -> 0 | F12: =COUNTIF('29151-HTP-001'!$A$5:$A$39,"RTD Cable") -> 0 | G12: =COUNTIF('29151-HTP-001'!$I$5:$I$39,"YES")&" / "&(COUNTA('29151-HTP-001'!$I$5:$I$39)-COUNTIF('29151-HTP-001'!$I$5:$I$39,"N/A")) -> 35 / 35 | H12: =COUNTIF('29151-HTP-001'!$J$5:$J$39,"YES")&" / "&(COUNTA('29151-HTP-001'!$J$5:$J$39)-COUNTIF('29151-HTP-001'!$J$5:$J$39,"N/A")) -> 17 / 35 | I12: =COUNTIF('29151-HTP-001'!$K$5:$K$39,"YES")&" / "&(COUNTA('29151-HTP-001'!$K$5:$K$39)-COUNTIF('29151-HTP-001'!$K$5:$K$39,"N/A")) -> 1 / 18 | J12: =COUNTIF('29151-HTP-001'!$L$5:$L$39,"YES")&" / "&(COUNTA('29151-HTP-001'!$L$5:$L$39)-COUNTIF('29151-HTP-001'!$L$5:$L$39,"N/A")) -> 0 / 18 | K12: =COUNTIF('29151-HTP-001'!$M$5:$M$39,"YES")&" / "&(COUNTA('29151-HTP-001'!$M$5:$M$39)-COUNTIF('29151-HTP-001'!$M$5:$M$39,"N/A")) -> 0 / 18 | L12: =COUNTIF('29151-HTP-001'!$N$5:$N$39,"YES")&" / "&(COUNTA('29151-HTP-001'!$N$5:$N$39)-COUNTIF('29151-HTP-001'!$N$5:$N$39,"N/A")) -> 17 / 17 | M12: =COUNTIF('29151-HTP-001'!$O$5:$O$39,"YES")&" / "&(COUNTA('29151-HTP-001'!$O$5:$O$39)-COUNTIF('29151-HTP-001'!$O$5:$O$39,"N/A")) -> 17 / 17 | N12: =COUNTIF('29151-HTP-001'!$P$5:$P$39,"YES")&" / "&(COUNTA('29151-HTP-001'!$P$5:$P$39)-COUNTIF('29151-HTP-001'!$P$5:$P$39,"N/A")) -> 0 / 0 | O12: =COUNTIF('29151-HTP-001'!$Q$5:$Q$39,"YES")&" / "&(COUNTA('29151-HTP-001'!$Q$5:$Q$39)-COUNTIF('29151-HTP-001'!$Q$5:$Q$39,"N/A")) -> 0 / 0 | P12: =COUNTIF('29151-HTP-001'!$R$5:$R$39,"YES")&" / "&(COUNTA('29151-HTP-001'!$R$5:$R$39)-COUNTIF('29151-HTP-001'!$R$5:$R$39,"N/A")) -> 17 / 35 | Q12: =COUNTIF('29151-HTP-001'!$S$5:$S$39,"YES")&" / "&(COUNTA('29151-HTP-001'!$S$5:$S$39)-COUNTIF('29151-HTP-001'!$S$5:$S$39,"N/A")) -> 17 / 35
A13: 29152-HTP-001 | B13: =COUNTA('29152-HTP-001'!$B$5:$B$37) -> 33 | C13: =COUNTIF('29152-HTP-001'!$A$5:$A$37,"EHT Trace") -> 16 | D13: =COUNTIF('29152-HTP-001'!$A$5:$A$37,"Power Cable") -> 17 | E13: =COUNTIF('29152-HTP-001'!$A$5:$A$37,"RTD") -> 0 | F13: =COUNTIF('29152-HTP-001'!$A$5:$A$37,"RTD Cable") -> 0 | G13: =COUNTIF('29152-HTP-001'!$I$5:$I$37,"YES")&" / "&(COUNTA('29152-HTP-001'!$I$5:$I$37)-COUNTIF('29152-HTP-001'!$I$5:$I$37,"N/A")) -> 33 / 33 | H13: =COUNTIF('29152-HTP-001'!$J$5:$J$37,"YES")&" / "&(COUNTA('29152-HTP-001'!$J$5:$J$37)-COUNTIF('29152-HTP-001'!$J$5:$J$37,"N/A")) -> 17 / 33 | I13: =COUNTIF('29152-HTP-001'!$K$5:$K$37,"YES")&" / "&(COUNTA('29152-HTP-001'!$K$5:$K$37)-COUNTIF('29152-HTP-001'!$K$5:$K$37,"N/A")) -> 0 / 16 | J13: =COUNTIF('29152-HTP-001'!$L$5:$L$37,"YES")&" / "&(COUNTA('29152-HTP-001'!$L$5:$L$37)-COUNTIF('29152-HTP-001'!$L$5:$L$37,"N/A")) -> 0 / 16 | K13: =COUNTIF('29152-HTP-001'!$M$5:$M$37,"YES")&" / "&(COUNTA('29152-HTP-001'!$M$5:$M$37)-COUNTIF('29152-HTP-001'!$M$5:$M$37,"N/A")) -> 0 / 16 | L13: =COUNTIF('29152-HTP-001'!$N$5:$N$37,"YES")&" / "&(COUNTA('29152-HTP-001'!$N$5:$N$37)-COUNTIF('29152-HTP-001'!$N$5:$N$37,"N/A")) -> 17 / 17 | M13: =COUNTIF('29152-HTP-001'!$O$5:$O$37,"YES")&" / "&(COUNTA('29152-HTP-001'!$O$5:$O$37)-COUNTIF('29152-HTP-001'!$O$5:$O$37,"N/A")) -> 17 / 17 | N13: =COUNTIF('29152-HTP-001'!$P$5:$P$37,"YES")&" / "&(COUNTA('29152-HTP-001'!$P$5:$P$37)-COUNTIF('29152-HTP-001'!$P$5:$P$37,"N/A")) -> 0 / 0 | O13: =COUNTIF('29152-HTP-001'!$Q$5:$Q$37,"YES")&" / "&(COUNTA('29152-HTP-001'!$Q$5:$Q$37)-COUNTIF('29152-HTP-001'!$Q$5:$Q$37,"N/A")) -> 0 / 0 | P13: =COUNTIF('29152-HTP-001'!$R$5:$R$37,"YES")&" / "&(COUNTA('29152-HTP-001'!$R$5:$R$37)-COUNTIF('29152-HTP-001'!$R$5:$R$37,"N/A")) -> 0 / 33 | Q13: =COUNTIF('29152-HTP-001'!$S$5:$S$37,"YES")&" / "&(COUNTA('29152-HTP-001'!$S$5:$S$37)-COUNTIF('29152-HTP-001'!$S$5:$S$37,"N/A")) -> 0 / 33
A14: Drain Tank Fieldbus | B14: =COUNTA('Drain Tank Fieldbus'!$B$5:$B$13) -> 9 | C14: =COUNTIF('Drain Tank Fieldbus'!$A$5:$A$13,"EHT Trace") -> 0 | D14: =COUNTIF('Drain Tank Fieldbus'!$A$5:$A$13,"Power Cable") -> 0 | E14: =COUNTIF('Drain Tank Fieldbus'!$A$5:$A$13,"RTD") -> 0 | F14: =COUNTIF('Drain Tank Fieldbus'!$A$5:$A$13,"RTD Cable") -> 0 | G14: =COUNTIF('Drain Tank Fieldbus'!$I$5:$I$13,"YES")&" / "&(COUNTA('Drain Tank Fieldbus'!$I$5:$I$13)-COUNTIF('Drain Tank Fieldbus'!$I$5:$I$13,"N/A")) -> 9 / 9 | H14: =COUNTIF('Drain Tank Fieldbus'!$J$5:$J$13,"YES")&" / "&(COUNTA('Drain Tank Fieldbus'!$J$5:$J$13)-COUNTIF('Drain Tank Fieldbus'!$J$5:$J$13,"N/A")) -> 9 / 9 | I14: =COUNTIF('Drain Tank Fieldbus'!$K$5:$K$13,"YES")&" / "&(COUNTA('Drain Tank Fieldbus'!$K$5:$K$13)-COUNTIF('Drain Tank Fieldbus'!$K$5:$K$13,"N/A")) -> 0 / 0 | J14: =COUNTIF('Drain Tank Fieldbus'!$L$5:$L$13,"YES")&" / "&(COUNTA('Drain Tank Fieldbus'!$L$5:$L$13)-COUNTIF('Drain Tank Fieldbus'!$L$5:$L$13,"N/A")) -> 0 / 0 | K14: =COUNTIF('Drain Tank Fieldbus'!$M$5:$M$13,"YES")&" / "&(COUNTA('Drain Tank Fieldbus'!$M$5:$M$13)-COUNTIF('Drain Tank Fieldbus'!$M$5:$M$13,"N/A")) -> 0 / 0 | L14: =COUNTIF('Drain Tank Fieldbus'!$N$5:$N$13,"YES")&" / "&(COUNTA('Drain Tank Fieldbus'!$N$5:$N$13)-COUNTIF('Drain Tank Fieldbus'!$N$5:$N$13,"N/A")) -> 0 / 0 | M14: =COUNTIF('Drain Tank Fieldbus'!$O$5:$O$13,"YES")&" / "&(COUNTA('Drain Tank Fieldbus'!$O$5:$O$13)-COUNTIF('Drain Tank Fieldbus'!$O$5:$O$13,"N/A")) -> 9 / 9 | N14: =COUNTIF('Drain Tank Fieldbus'!$P$5:$P$13,"YES")&" / "&(COUNTA('Drain Tank Fieldbus'!$P$5:$P$13)-COUNTIF('Drain Tank Fieldbus'!$P$5:$P$13,"N/A")) -> 0 / 0 | O14: =COUNTIF('Drain Tank Fieldbus'!$Q$5:$Q$13,"YES")&" / "&(COUNTA('Drain Tank Fieldbus'!$Q$5:$Q$13)-COUNTIF('Drain Tank Fieldbus'!$Q$5:$Q$13,"N/A")) -> 0 / 0 | P14: =COUNTIF('Drain Tank Fieldbus'!$R$5:$R$13,"YES")&" / "&(COUNTA('Drain Tank Fieldbus'!$R$5:$R$13)-COUNTIF('Drain Tank Fieldbus'!$R$5:$R$13,"N/A")) -> 9 / 9 | Q14: =COUNTIF('Drain Tank Fieldbus'!$S$5:$S$13,"YES")&" / "&(COUNTA('Drain Tank Fieldbus'!$S$5:$S$13)-COUNTIF('Drain Tank Fieldbus'!$S$5:$S$13,"N/A")) -> 9 / 9
A15: Total | B15: =SUM(B5:B14) -> 1377 | C15: =SUM(C5:C14) -> 587 | D15: =SUM(D5:D14) -> 296 | E15: =SUM(E5:E14) -> 232 | F15: =SUM(F5:F14) -> 253

Sheet 29103-HTP-102
A1: 29103-HTP-102
I3: CHECKSHEETS | T3: TEST RESULTS
A4: Type | B4: Tag | C4: Circuit | D4: Controller | E4: System | F4: ISO / Dwg | G4: Form | H4: File | I4: ITR | J4: Visual | K4: Rec. Megger | L4: Pre-Insul Megger | M4: Post-Insul Megger | N4: Cable IR | O4: Cable Cont. | P4: RTD Pre | Q4: RTD Post | R4: Dated | S4: Complete | T4: Visual Initials | U4: Rec. IR | V4: Rec. Cont. | W4: Rec. Date | X4: Pre IR | Y4: Pre Cont. | Z4: Pre Date | AA4: Post IR | AB4: Post Cont. | AC4: Post Date | AD4: Cable IR | AE4: Cable Cont. | AF4: Meter | AG4: RTD Ω | AH4: RTD Pre (S/C/Com) | AI4: RTD Post (S/C/Com) | AJ4: Part # / Cable | AK4: Length / Size | AL4: Inspected By | AM4: Date | AN4: Remarks
A5: EHT Trace | B5: 29103-ET-A001-1-1 | C5: 29103-ET-A001-1 | D5: HTC-31 / CB-31 | E5: 29103-A-001 | F5: 29103-65R-ET-A001-01-01 | G5: 13.1 | H5: 29103-ET-A001-1-1.pdf | I5: =IF($H5<>"","YES","NO") -> YES | J5: =IF(N($T5)>0,"YES","NO") -> NO | K5: =IF(OR($A5="EHT Trace"),IF(AND($U5<>"",$V5<>""),"YES","NO"),"N/A") -> NO | L5: =IF(OR($A5="EHT Trace"),IF(AND($X5<>"",$Y5<>""),"YES","NO"),"N/A") -> NO | M5: =IF(OR($A5="EHT Trace"),IF(AND($AA5<>"",$AB5<>""),"YES","NO"),"N/A") -> NO | N5: =IF(OR($A5="Power Cable"),IF(AND($AD5<>""),"YES","NO"),"N/A") -> N/A | O5: =IF(OR($A5="Power Cable",$A5="RTD Cable",$A5="Fieldbus Cable"),IF(AND($AE5<>""),"YES","NO"),"N/A") -> N/A | P5: =IF(OR($A5="RTD"),IF(AND($AH5<>""),"YES","NO"),"N/A") -> N/A | Q5: =IF(OR($A5="RTD"),IF(AND($AI5<>""),"YES","NO"),"N/A") -> N/A | R5: =IF(OR($AM5<>"",$Z5<>"",$AC5<>""),"YES","NO") -> NO | S5: =IF(COUNTIF(I5:R5,"NO")=0,"YES","NO") -> NO | AJ5: 5HTV2-CT | AK5: 5.2 m m | AL5: Levy Ostrup
A6: EHT Trace | B6: 29103-ET-A001-1-2 | C6: 29103-ET-A001-1 | D6: HTC-31 / CB-31 | E6: 29103-A-001 | F6: 29103-65R-ET-A001-01-01 | G6: 13.1 | H6: 29103-ET-A001-1-2.pdf | I6: =IF($H6<>"","YES","NO") -> YES | J6: =IF(N($T6)>0,"YES","NO") -> NO | K6: =IF(OR($A6="EHT Trace"),IF(AND($U6<>"",$V6<>""),"YES","NO"),"N/A") -> NO | L6: =IF(OR($A6="EHT Trace"),IF(AND($X6<>"",$Y6<>""),"YES","NO"),"N/A") -> NO | M6: =IF(OR($A6="EHT Trace"),IF(AND($AA6<>"",$AB6<>""),"YES","NO"),"N/A") -> NO | N6: =IF(OR($A6="Power Cable"),IF(AND($AD6<>""),"YES","NO"),"N/A") -> N/A | O6: =IF(OR($A6="Power Cable",$A6="RTD Cable",$A6="Fieldbus Cable"),IF(AND($AE6<>""),"YES","NO"),"N/A") -> N/A | P6: =IF(OR($A6="RTD"),IF(AND($AH6<>""),"YES","NO"),"N/A") -> N/A | Q6: =IF(OR($A6="RTD"),IF(AND($AI6<>""),"YES","NO"),"N/A") -> N/A | R6: =IF(OR($AM6<>"",$Z6<>"",$AC6<>""),"YES","NO") -> NO | S6: =IF(COUNTIF(I6:R6,"NO")=0,"YES","NO") -> NO | AJ6: 5HTV2-CT | AK6: 5.2 m m | AL6: Levy Ostrup
A7: EHT Trace | B7: 29103-ET-HC1901-1-1 | C7: 29103-ET-HC1901-1 | D7: HTC-05 / CB-05 | E7: 29103-HC-1901 | F7: 29103-65R-ET-HC1901-01-01 | G7: 13.1 | H7: 29103-ET-HC1901-1-1.pdf | I7: =IF($H7<>"","YES","NO") -> YES | J7: =IF(N($T7)>0,"YES","NO") -> NO | K7: =IF(OR($A7="EHT Trace"),IF(AND($U7<>"",$V7<>""),"YES","NO"),"N/A") -> NO | L7: =IF(OR($A7="EHT Trace"),IF(AND($X7<>"",$Y7<>""),"YES","NO"),"N/A") -> NO | M7: =IF(OR($A7="EHT Trace"),IF(AND($AA7<>"",$AB7<>""),"YES","NO"),"N/A") -> NO | N7: =IF(OR($A7="Power Cable"),IF(AND($AD7<>""),"YES","NO"),"N/A") -> N/A | O7: =IF(OR($A7="Power Cable",$A7="RTD Cable",$A7="Fieldbus Cable"),IF(AND($AE7<>""),"YES","NO"),"N/A") -> N/A | P7: =IF(OR($A7="RTD"),IF(AND($AH7<>""),"YES","NO"),"N/A") -> N/A | Q7: =IF(OR($A7="RTD"),IF(AND($AI7<>""),"YES","NO"),"N/A") -> N/A | R7: =IF(OR($AM7<>"",$Z7<>"",$AC7<>""),"YES","NO") -> NO | S7: =IF(COUNTIF(I7:R7,"NO")=0,"YES","NO") -> NO | AJ7: 20HTV2-CT | AK7: 12.1 m m | AL7: Levy Ostrup
A8: EHT Trace | B8: 29103-ET-HC1902-1-1 | C8: 29103-ET-HC1902-1 | D8: 29103-AMB-015 | E8: 29103-HC-1902 | F8: 29103-65R-ET-HC1902-01-01 | G8: 13.1 | H8: 29103-ET-HC1902-1-1.pdf | I8: =IF($H8<>"","YES","NO") -> YES | J8: =IF(N($T8)>0,"YES","NO") -> NO | K8: =IF(OR($A8="EHT Trace"),IF(AND($U8<>"",$V8<>""),"YES","NO"),"N/A") -> NO | L8: =IF(OR($A8="EHT Trace"),IF(AND($X8<>"",$Y8<>""),"YES","NO"),"N/A") -> NO | M8: =IF(OR($A8="EHT Trace"),IF(AND($AA8<>"",$AB8<>""),"YES","NO"),"N/A") -> NO | N8: =IF(OR($A8="Power Cable"),IF(AND($AD8<>""),"YES","NO"),"N/A") -> N/A | O8: =IF(OR($A8="Power Cable",$A8="RTD Cable",$A8="Fieldbus Cable"),IF(AND($AE8<>""),"YES","NO"),"N/A") -> N/A | P8: =IF(OR($A8="RTD"),IF(AND($AH8<>""),"YES","NO"),"N/A") -> N/A | Q8: =IF(OR($A8="RTD"),IF(AND($AI8<>""),"YES","NO"),"N/A") -> N/A | R8: =IF(OR($AM8<>"",$Z8<>"",$AC8<>""),"YES","NO") -> NO | S8: =IF(COUNTIF(I8:R8,"NO")=0,"YES","NO") -> NO | AJ8: 8HTV2-CT | AK8: 17 m m | AL8: Levy Ostrup
A9: EHT Trace | B9: 29103-ET-HC1903-1-1 | C9: 29103-ET-HC1903-1 | D9: HTC-04 / CB-04 | E9: 29103-HC-1903, 29103-HC-1902 | F9: 29103-65R-ET-HC1903-01-01 | G9: 13.1 | H9: 29103-ET-HC1903-1-1.pdf | I9: =IF($H9<>"","YES","NO") -> YES | J9: =IF(N($T9)>0,"YES","NO") -> NO | K9: =IF(OR($A9="EHT Trace"),IF(AND($U9<>"",$V9<>""),"YES","NO"),"N/A") -> NO | L9: =IF(OR($A9="EHT Trace"),IF(AND($X9<>"",$Y9<>""),"YES","NO"),"N/A") -> NO | M9: =IF(OR($A9="EHT Trace"),IF(AND($AA9<>"",$AB9<>""),"YES","NO"),"N/A") -> NO | N9: =IF(OR($A9="Power Cable"),IF(AND($AD9<>""),"YES","NO"),"N/A") -> N/A | O9: =IF(OR($A9="Power Cable",$A9="RTD Cable",$A9="Fieldbus Cable"),IF(AND($AE9<>""),"YES","NO"),"N/A") -> N/A | P9: =IF(OR($A9="RTD"),IF(AND($AH9<>""),"YES","NO"),"N/A") -> N/A | Q9: =IF(OR($A9="RTD"),IF(AND($AI9<>""),"YES","NO"),"N/A") -> N/A | R9: =IF(OR($AM9<>"",$Z9<>"",$AC9<>""),"YES","NO") -> NO | S9: =IF(COUNTIF(I9:R9,"NO")=0,"YES","NO") -> NO | AJ9: 8HTV2-CT | AK9: 28.7 m m | AL9: Levy Ostrup
A10: EHT Trace | B10: 29103-ET-HC1903-1-2 | C10: 29103-ET-HC1903-1 | D10: HTC-04 / CB-04 | E10: 29103-HC-1904 | F10: 29103-65R-ET-HC1903-01-01 | G10: 13.1 | H10: 29103-ET-HC1903-1-2.pdf | I10: =IF($H10<>"","YES","NO") -> YES | J10: =IF(N($T10)>0,"YES","NO") -> NO | K10: =IF(OR($A10="EHT Trace"),IF(AND($U10<>"",$V10<>""),"YES","NO"),"N/A") -> NO | L10: =IF(OR($A10="EHT Trace"),IF(AND($X10<>"",$Y10<>""),"YES","NO"),"N/A") -> NO | M10: =IF(OR($A10="EHT Trace"),IF(AND($AA10<>"",$AB10<>""),"YES","NO"),"N/A") -> NO | N10: =IF(OR($A10="Power Cable"),IF(AND($AD10<>""),"YES","NO"),"N/A") -> N/A | O10: =IF(OR($A10="Power Cable",$A10="RTD Cable",$A10="Fieldbus Cable"),IF(AND($AE10<>""),"YES","NO"),"N/A") -> N/A | P10: =IF(OR($A10="RTD"),IF(AND($AH10<>""),"YES","NO"),"N/A") -> N/A | Q10: =IF(OR($A10="RTD"),IF(AND($AI10<>""),"YES","NO"),"N/A") -> N/A | R10: =IF(OR($AM10<>"",$Z10<>"",$AC10<>""),"YES","NO") -> NO | S10: =IF(COUNTIF(I10:R10,"NO")=0,"YES","NO") -> NO | AJ10: 8HTV2-CT | AK10: 32 m m | AL10: Levy Ostrup
A11: EHT Trace | B11: 29103-ET-HC1905-1-1 | C11: 29103-ET-HC1905-1 | D11: 29103-AMB-015 | E11: 29103-HC-1910, 29103-HC-1905 | F11: 29103-65R-ET-HC1905-01-01 | G11: 13.1 | H11: 29103-ET-HC1905-1-1.pdf | I11: =IF($H11<>"","YES","NO") -> YES | J11: =IF(N($T11)>0,"YES","NO") -> NO | K11: =IF(OR($A11="EHT Trace"),IF(AND($U11<>"",$V11<>""),"YES","NO"),"N/A") -> NO | L11: =IF(OR($A11="EHT Trace"),IF(AND($X11<>"",$Y11<>""),"YES","NO"),"N/A") -> NO | M11: =IF(OR($A11="EHT Trace"),IF(AND($AA11<>"",$AB11<>""),"YES","NO"),"N/A") -> NO | N11: =IF(OR($A11="Power Cable"),IF(AND($AD11<>""),"YES","NO"),"N/A") -> N/A | O11: =IF(OR($A11="Power Cable",$A11="RTD Cable",$A11="Fieldbus Cable"),IF(AND($AE11<>""),"YES","NO"),"N/A") -> N/A | P11: =IF(OR($A11="RTD"),IF(AND($AH11<>""),"YES","NO"),"N/A") -> N/A | Q11: =IF(OR($A11="RTD"),IF(AND($AI11<>""),"YES","NO"),"N/A") -> N/A | R11: =IF(OR($AM11<>"",$Z11<>"",$AC11<>""),"YES","NO") -> NO | S11: =IF(COUNTIF(I11:R11,"NO")=0,"YES","NO") -> NO | AJ11: 8HTV2-CT | AK11: 55.5 m m | AL11: Levy Ostrup
A12: EHT Trace | B12: 29103-ET-HC1906-1-1 | C12: 29103-ET-HC1906-1 | D12: HTC-06 / CB-06 | E12: 29103-HC-1906, 29103-HC-1902 | F12: 29103-65R-ET-HC1906-01-01 | G12: 13.1 | H12: 29103-ET-HC1906-1-1.pdf | I12: =IF($H12<>"","YES","NO") -> YES | J12: =IF(N($T12)>0,"YES","NO") -> NO | K12: =IF(OR($A12="EHT Trace"),IF(AND($U12<>"",$V12<>""),"YES","NO"),"N/A") -> NO | L12: =IF(OR($A12="EHT Trace"),IF(AND($X12<>"",$Y12<>""),"YES","NO"),"N/A") -> NO | M12: =IF(OR($A12="EHT Trace"),IF(AND($AA12<>"",$AB12<>""),"YES","NO"),"N/A") -> NO | N12: =IF(OR($A12="Power Cable"),IF(AND($AD12<>""),"YES","NO"),"N/A") -> N/A | O12: =IF(OR($A12="Power Cable",$A12="RTD Cable",$A12="Fieldbus Cable"),IF(AND($AE12<>""),"YES","NO"),"N/A") -> N/A | P12: =IF(OR($A12="RTD"),IF(AND($AH12<>""),"YES","NO"),"N/A") -> N/A | Q12: =IF(OR($A12="RTD"),IF(AND($AI12<>""),"YES","NO"),"N/A") -> N/A | R12: =IF(OR($AM12<>"",$Z12<>"",$AC12<>""),"YES","NO") -> NO | S12: =IF(COUNTIF(I12:R12,"NO")=0,"YES","NO") -> NO | AJ12: 8HTV2-CT | AK12: 29.9 m m | AL12: Levy Ostrup
A13: EHT Trace | B13: 29103-ET-HC1906-1-2 | C13: 29103-ET-HC1906-1 | D13: HTC-06 / CB-06 | E13: 29103-HC-1907 | F13: 29103-65R-ET-HC1906-01-01 | G13: 13.1 | H13: 29103-ET-HC1906-1-2.pdf | I13: =IF($H13<>"","YES","NO") -> YES | J13: =IF(N($T13)>0,"YES","NO") -> NO | K13: =IF(OR($A13="EHT Trace"),IF(AND($U13<>"",$V13<>""),"YES","NO"),"N/A") -> NO | L13: =IF(OR($A13="EHT Trace"),IF(AND($X13<>"",$Y13<>""),"YES","NO"),"N/A") -> NO | M13: =IF(OR($A13="EHT Trace"),IF(AND($AA13<>"",$AB13<>""),"YES","NO"),"N/A") -> NO | N13: =IF(OR($A13="Power Cable"),IF(AND($AD13<>""),"YES","NO"),"N/A") -> N/A | O13: =IF(OR($A13="Power Cable",$A13="RTD Cable",$A13="Fieldbus Cable"),IF(AND($AE13<>""),"YES","NO"),"N/A") -> N/A | P13: =IF(OR($A13="RTD"),IF(AND($AH13<>""),"YES","NO"),"N/A") -> N/A | Q13: =IF(OR($A13="RTD"),IF(AND($AI13<>""),"YES","NO"),"N/A") -> N/A | R13: =IF(OR($AM13<>"",$Z13<>"",$AC13<>""),"YES","NO") -> NO | S13: =IF(COUNTIF(I13:R13,"NO")=0,"YES","NO") -> NO | AJ13: 8HTV2-CT | AK13: 31.5 m m | AL13: Levy Ostrup
A14: EHT Trace | B14: 29103-ET-HC1909-1-1 | C14: 29103-ET-HC1909-1 | D14: 29103-AMB-015 | E14: 29103-HC-1909, 29103-HC-1908 | F14: 29103-65R-ET-HC1909-01-01 | G14: 13.1 | H14: 29103-ET-HC1909-1-1.pdf | I14: =IF($H14<>"","YES","NO") -> YES | J14: =IF(N($T14)>0,"YES","NO") -> NO | K14: =IF(OR($A14="EHT Trace"),IF(AND($U14<>"",$V14<>""),"YES","NO"),"N/A") -> NO | L14: =IF(OR($A14="EHT Trace"),IF(AND($X14<>"",$Y14<>""),"YES","NO"),"N/A") -> NO | M14: =IF(OR($A14="EHT Trace"),IF(AND($AA14<>"",$AB14<>""),"YES","NO"),"N/A") -> NO | N14: =IF(OR($A14="Power Cable"),IF(AND($AD14<>""),"YES","NO"),"N/A") -> N/A | O14: =IF(OR($A14="Power Cable",$A14="RTD Cable",$A14="Fieldbus Cable"),IF(AND($AE14<>""),"YES","NO"),"N/A") -> N/A | P14: =IF(OR($A14="RTD"),IF(AND($AH14<>""),"YES","NO"),"N/A") -> N/A | Q14: =IF(OR($A14="RTD"),IF(AND($AI14<>""),"YES","NO"),"N/A") -> N/A | R14: =IF(OR($AM14<>"",$Z14<>"",$AC14<>""),"YES","NO") -> NO | S14: =IF(COUNTIF(I14:R14,"NO")=0,"YES","NO") -> NO | AJ14: 8HTV2-CT | AK14: 49 m m | AL14: Levy Ostrup
A15: EHT Trace | B15: 29103-ET-MT0001-1-1 | C15: 29103-ET-MT0001-1 | D15: HTC-09 / CB-09 | E15: 29103-MT-0001 | F15: 29103-65R-ET-MT0001-01-01 | G15: 13.1 | H15: 29103-ET-MT0001-1-1.pdf | I15: =IF($H15<>"","YES","NO") -> YES | J15: =IF(N($T15)>0,"YES","NO") -> NO | K15: =IF(OR($A15="EHT Trace"),IF(AND($U15<>"",$V15<>""),"YES","NO"),"N/A") -> NO | L15: =IF(OR($A15="EHT Trace"),IF(AND($X15<>"",$Y15<>""),"YES","NO"),"N/A") -> NO | M15: =IF(OR($A15="EHT Trace"),IF(AND($AA15<>"",$AB15<>""),"YES","NO"),"N/A") -> NO | N15: =IF(OR($A15="Power Cable"),IF(AND($AD15<>""),"YES","NO"),"N/A") -> N/A | O15: =IF(OR($A15="Power Cable",$A15="RTD Cable",$A15="Fieldbus Cable"),IF(AND($AE15<>""),"YES","NO"),"N/A") -> N/A | P15: =IF(OR($A15="RTD"),IF(AND($AH15<>""),"YES","NO"),"N/A") -> N/A | Q15: =IF(OR($A15="RTD"),IF(AND($AI15<>""),"YES","NO"),"N/A") -> N/A | R15: =IF(OR($AM15<>"",$Z15<>"",$AC15<>""),"YES","NO") -> NO | S15: =IF(COUNTIF(I15:R15,"NO")=0,"YES","NO") -> NO | AJ15: 20HTV2-CT | AK15: 3.7 m m | AL15: Levy Ostrup
A16: EHT Trace | B16: 29103-ET-MT0001-1-2 | C16: 29103-ET-MT0001-1 | D16: HTC-09 / CB-09 | E16: 29103-MT-0001 | F16: 29103-65R-ET-MT0001-01-01 | G16: 13.1 | H16: 29103-ET-MT0001-1-2.pdf | I16: =IF($H16<>"","YES","NO") -> YES | J16: =IF(N($T16)>0,"YES","NO") -> NO | K16: =IF(OR($A16="EHT Trace"),IF(AND($U16<>"",$V16<>""),"YES","NO"),"N/A") -> NO | L16: =IF(OR($A16="EHT Trace"),IF(AND($X16<>"",$Y16<>""),"YES","NO"),"N/A") -> NO | M16: =IF(OR($A16="EHT Trace"),IF(AND($AA16<>"",$AB16<>""),"YES","NO"),"N/A") -> NO | N16: =IF(OR($A16="Power Cable"),IF(AND($AD16<>""),"YES","NO"),"N/A") -> N/A | O16: =IF(OR($A16="Power Cable",$A16="RTD Cable",$A16="Fieldbus Cable"),IF(AND($AE16<>""),"YES","NO"),"N/A") -> N/A | P16: =IF(OR($A16="RTD"),IF(AND($AH16<>""),"YES","NO"),"N/A") -> N/A | Q16: =IF(OR($A16="RTD"),IF(AND($AI16<>""),"YES","NO"),"N/A") -> N/A | R16: =IF(OR($AM16<>"",$Z16<>"",$AC16<>""),"YES","NO") -> NO | S16: =IF(COUNTIF(I16:R16,"NO")=0,"YES","NO") -> NO | AJ16: 20HTV2-CT | AK16: 12.3 m m | AL16: Levy Ostrup
... A28: EHT Trace | B28: 29103-ET-P001B-4-2 | C28: 29103-ET-P001B-4 | D28: HTC-16 / CB-16 | E28: 29103-P-001B | F28: 29103-65R-ET-P001B-04-01 | G28: 13.1 | H28: 29103-ET-P001B-4-2.pdf | I28: =IF($H28<>"","YES","NO") -> YES | J28: =IF(N($T28)>0,"YES","NO") -> NO | K28: =IF(OR($A28="EHT Trace"),IF(AND($U28<>"",$V28<>""),"YES","NO"),"N/A") -> NO | L28: =IF(OR($A28="EHT Trace"),IF(AND($X28<>"",$Y28<>""),"YES","NO"),"N/A") -> NO | M28: =IF(OR($A28="EHT Trace"),IF(AND($AA28<>"",$AB28<>""),"YES","NO"),"N/A") -> NO | N28: =IF(OR($A28="Power Cable"),IF(AND($AD28<>""),"YES","NO"),"N/A") -> N/A | O28: =IF(OR($A28="Power Cable",$A28="RTD Cable",$A28="Fieldbus Cable"),IF(AND($AE28<>""),"YES","NO"),"N/A") -> N/A | P28: =IF(OR($A28="RTD"),IF(AND($AH28<>""),"YES","NO"),"N/A") -> N/A | Q28: =IF(OR($A28="RTD"),IF(AND($AI28<>""),"YES","NO"),"N/A") -> N/A | R28: =IF(OR($AM28<>"",$Z28<>"",$AC28<>""),"YES","NO") -> NO | S28: =IF(COUNTIF(I28:R28,"NO")=0,"YES","NO") -> NO | AJ28: 10XTVR2-CT | AK28: 24.6 m m | AL28: Levy Ostrup
A29: EHT Trace | B29: 29103-ET-P1003-1-1 | C29: 29103-ET-P1003-1 | D29: HTC-19 / CB-19 | E29: 29103-P-1003 | F29: 29103-65R-ET-P1003-01-01 | G29: 13.1 | H29: 29103-ET-P1003-1-1.pdf | I29: =IF($H29<>"","YES","NO") -> YES | J29: =IF(N($T29)>0,"YES","NO") -> NO | K29: =IF(OR($A29="EHT Trace"),IF(AND($U29<>"",$V29<>""),"YES","NO"),"N/A") -> YES | L29: =IF(OR($A29="EHT Trace"),IF(AND($X29<>"",$Y29<>""),"YES","NO"),"N/A") -> NO | M29: =IF(OR($A29="EHT Trace"),IF(AND($AA29<>"",$AB29<>""),"YES","NO"),"N/A") -> NO | N29: =IF(OR($A29="Power Cable"),IF(AND($AD29<>""),"YES","NO"),"N/A") -> N/A | O29: =IF(OR($A29="Power Cable",$A29="RTD Cable",$A29="Fieldbus Cable"),IF(AND($AE29<>""),"YES","NO"),"N/A") -> N/A | P29: =IF(OR($A29="RTD"),IF(AND($AH29<>""),"YES","NO"),"N/A") -> N/A | Q29: =IF(OR($A29="RTD"),IF(AND($AI29<>""),"YES","NO"),"N/A") -> N/A | R29: =IF(OR($AM29<>"",$Z29<>"",$AC29<>""),"YES","NO") -> NO | S29: =IF(COUNTIF(I29:R29,"NO")=0,"YES","NO") -> NO | U29: >2.2 GΩ | V29: 38.1 Ω | W29: 2026-05-17 | AJ29: D/32SQ3374/30.1M/1899/277/2.1M/LS23A/X/N12 | AK29: 30.1 m m | AL29: Levy Ostrup
A30: EHT Trace | B30: 29103-ET-P1003-1-2 | C30: 29103-ET-P1003-1 | D30: HTC-19 / CB-19 | E30: 29103-P-1003 | F30: 29103-65R-ET-P1003-01-01 | G30: 13.1 | H30: 29103-ET-P1003-1-2.pdf | I30: =IF($H30<>"","YES","NO") -> YES | J30: =IF(N($T30)>0,"YES","NO") -> NO | K30: =IF(OR($A30="EHT Trace"),IF(AND($U30<>"",$V30<>""),"YES","NO"),"N/A") -> YES | L30: =IF(OR($A30="EHT Trace"),IF(AND($X30<>"",$Y30<>""),"YES","NO"),"N/A") -> NO | M30: =IF(OR($A30="EHT Trace"),IF(AND($AA30<>"",$AB30<>""),"YES","NO"),"N/A") -> NO | N30: =IF(OR($A30="Power Cable"),IF(AND($AD30<>""),"YES","NO"),"N/A") -> N/A | O30: =IF(OR($A30="Power Cable",$A30="RTD Cable",$A30="Fieldbus Cable"),IF(AND($AE30<>""),"YES","NO"),"N/A") -> N/A | P30: =IF(OR($A30="RTD"),IF(AND($AH30<>""),"YES","NO"),"N/A") -> N/A | Q30: =IF(OR($A30="RTD"),IF(AND($AI30<>""),"YES","NO"),"N/A") -> N/A | R30: =IF(OR($AM30<>"",$Z30<>"",$AC30<>""),"YES","NO") -> NO | S30: =IF(COUNTIF(I30:R30,"NO")=0,"YES","NO") -> NO | U30: >2.2 GΩ | V30: 38.1 Ω | W30: 2026-05-17 | AJ30: D/32SQ3374/30.1M/1899/277/2.1M/LS23A/X/N12 | AK30: 30.1 m m | AL30: Levy Ostrup
A31: EHT Trace | B31: 29103-ET-P1004-1-1 | C31: 29103-ET-P1004-1 | D31: HTC-20 / CB-20 | E31: 29103-P-1004 | F31: 29103-65R-ET-P1004-01-01 | G31: 13.1 | H31: 29103-ET-P1004-1-1.pdf | I31: =IF($H31<>"","YES","NO") -> YES | J31: =IF(N($T31)>0,"YES","NO") -> NO | K31: =IF(OR($A31="EHT Trace"),IF(AND($U31<>"",$V31<>""),"YES","NO"),"N/A") -> YES | L31: =IF(OR($A31="EHT Trace"),IF(AND($X31<>"",$Y31<>""),"YES","NO"),"N/A") -> NO | M31: =IF(OR($A31="EHT Trace"),IF(AND($AA31<>"",$AB31<>""),"YES","NO"),"N/A") -> NO | N31: =IF(OR($A31="Power Cable"),IF(AND($AD31<>""),"YES","NO"),"N/A") -> N/A | O31: =IF(OR($A31="Power Cable",$A31="RTD Cable",$A31="Fieldbus Cable"),IF(AND($AE31<>""),"YES","NO"),"N/A") -> N/A | P31: =IF(OR($A31="RTD"),IF(AND($AH31<>""),"YES","NO"),"N/A") -> N/A | Q31: =IF(OR($A31="RTD"),IF(AND($AI31<>""),"YES","NO"),"N/A") -> N/A | R31: =IF(OR($AM31<>"",$Z31<>"",$AC31<>""),"YES","NO") -> NO | S31: =IF(COUNTIF(I31:R31,"NO")=0,"YES","NO") -> NO | U31: >2.2 GΩ | V31: 30.3 Ω | W31: 2026-05-17 | AJ31: D/32SQ3200/44.1M/2426/277/2.1M/LS23A/X/N12 | AK31: 44.1 m m | AL31: Levy Ostrup
A32: EHT Trace | B32: 29103-ET-P1004-1-2 | C32: 29103-ET-P1004-1 | D32: HTC-20 / CB-20 | E32: 29103-P-1004 | F32: 29103-65R-ET-P1004-01-01 | G32: 13.1 | H32: 29103-ET-P1004-1-2.pdf | I32: =IF($H32<>"","YES","NO") -> YES | J32: =IF(N($T32)>0,"YES","NO") -> NO | K32: =IF(OR($A32="EHT Trace"),IF(AND($U32<>"",$V32<>""),"YES","NO"),"N/A") -> YES | L32: =IF(OR($A32="EHT Trace"),IF(AND($X32<>"",$Y32<>""),"YES","NO"),"N/A") -> NO | M32: =IF(OR($A32="EHT Trace"),IF(AND($AA32<>"",$AB32<>""),"YES","NO"),"N/A") -> NO | N32: =IF(OR($A32="Power Cable"),IF(AND($AD32<>""),"YES","NO"),"N/A") -> N/A | O32: =IF(OR($A32="Power Cable",$A32="RTD Cable",$A32="Fieldbus Cable"),IF(AND($AE32<>""),"YES","NO"),"N/A") -> N/A | P32: =IF(OR($A32="RTD"),IF(AND($AH32<>""),"YES","NO"),"N/A") -> N/A | Q32: =IF(OR($A32="RTD"),IF(AND($AI32<>""),"YES","NO"),"N/A") -> N/A | R32: =IF(OR($AM32<>"",$Z32<>"",$AC32<>""),"YES","NO") -> NO | S32: =IF(COUNTIF(I32:R32,"NO")=0,"YES","NO") -> NO | U32: >2.2 GΩ | V32: 30.2 Ω | W32: 2026-05-17 | AJ32: D/32SQ3200/44.1M/2426/277/2.1M/LS23A/X/N12 | AK32: 44.1 m m | AL32: Levy Ostrup
A33: EHT Trace | B33: 29103-ET-P1920-1-1 | C33: 29103-ET-P1920-1 | D33: HTC-22 / CB-22 | E33: 29103-P-1920 | F33: 29103-65R-ET-P1920-01-01 | G33: 13.1 | H33: 29103-ET-P1920-1-1.pdf | I33: =IF($H33<>"","YES","NO") -> YES | J33: =IF(N($T33)>0,"YES","NO") -> NO | K33: =IF(OR($A33="EHT Trace"),IF(AND($U33<>"",$V33<>""),"YES","NO"),"N/A") -> NO | L33: =IF(OR($A33="EHT Trace"),IF(AND($X33<>"",$Y33<>""),"YES","NO"),"N/A") -> NO | M33: =IF(OR($A33="EHT Trace"),IF(AND($AA33<>"",$AB33<>""),"YES","NO"),"N/A") -> NO | N33: =IF(OR($A33="Power Cable"),IF(AND($AD33<>""),"YES","NO"),"N/A") -> N/A | O33: =IF(OR($A33="Power Cable",$A33="RTD Cable",$A33="Fieldbus Cable"),IF(AND($AE33<>""),"YES","NO"),"N/A") -> N/A | P33: =IF(OR($A33="RTD"),IF(AND($AH33<>""),"YES","NO"),"N/A") -> N/A | Q33: =IF(OR($A33="RTD"),IF(AND($AI33<>""),"YES","NO"),"N/A") -> N/A | R33: =IF(OR($AM33<>"",$Z33<>"",$AC33<>""),"YES","NO") -> NO | S33: =IF(COUNTIF(I33:R33,"NO")=0,"YES","NO") -> NO | AJ33: 5HTV2-CT | AK33: 117.5 m m | AL33: Levy Ostrup
A34: EHT Trace | B34: 29103-ET-P1920-2-1 | C34: 29103-ET-P1920-2 | D34: 29103-AMB-016 | E34: 29103-P-1920 | F34: 29103-65R-ET-P1920-02-01 | G34: 13.1 | H34: 29103-ET-P1920-2-1.pdf | I34: =IF($H34<>"","YES","NO") -> YES | J34: =IF(N($T34)>0,"YES","NO") -> NO | K34: =IF(OR($A34="EHT Trace"),IF(AND($U34<>"",$V34<>""),"YES","NO"),"N/A") -> NO | L34: =IF(OR($A34="EHT Trace"),IF(AND($X34<>"",$Y34<>""),"YES","NO"),"N/A") -> NO | M34: =IF(OR($A34="EHT Trace"),IF(AND($AA34<>"",$AB34<>""),"YES","NO"),"N/A") -> NO | N34: =IF(OR($A34="Power Cable"),IF(AND($AD34<>""),"YES","NO"),"N/A") -> N/A | O34: =IF(OR($A34="Power Cable",$A34="RTD Cable",$A34="Fieldbus Cable"),IF(AND($AE34<>""),"YES","NO"),"N/A") -> N/A | P34: =IF(OR($A34="RTD"),IF(AND($AH34<>""),"YES","NO"),"N/A") -> N/A | Q34: =IF(OR($A34="RTD"),IF(AND($AI34<>""),"YES","NO"),"N/A") -> N/A | R34: =IF(OR($AM34<>"",$Z34<>"",$AC34<>""),"YES","NO") -> NO | S34: =IF(COUNTIF(I34:R34,"NO")=0,"YES","NO") -> NO | AJ34: 5HTV2-CT | AK34: 32.4 m m | AL34: Levy Ostrup
A35: EHT Trace | B35: 29103-ET-PG1901-1-1 | C35: 29103-ET-PG1901-1 | D35: 29103-AMB-016 | E35: 29103-PG-1902, 29103-PG-1901 | F35: 29103-65R-ET-PG1901-01-01 | G35: 13.1 | H35: 29103-ET-PG1901-1-1.pdf | I35: =IF($H35<>"","YES","NO") -> YES | J35: =IF(N($T35)>0,"YES","NO") -> NO | K35: =IF(OR($A35="EHT Trace"),IF(AND($U35<>"",$V35<>""),"YES","NO"),"N/A") -> NO | L35: =IF(OR($A35="EHT Trace"),IF(AND($X35<>"",$Y35<>""),"YES","NO"),"N/A") -> NO | M35: =IF(OR($A35="EHT Trace"),IF(AND($AA35<>"",$AB35<>""),"YES","NO"),"N/A") -> NO | N35: =IF(OR($A35="Power Cable"),IF(AND($AD35<>""),"YES","NO"),"N/A") -> N/A | O35: =IF(OR($A35="Power Cable",$A35="RTD Cable",$A35="Fieldbus Cable"),IF(AND($AE35<>""),"YES","NO"),"N/A") -> N/A | P35: =IF(OR($A35="RTD"),IF(AND($AH35<>""),"YES","NO"),"N/A") -> N/A | Q35: =IF(OR($A35="RTD"),IF(AND($AI35<>""),"YES","NO"),"N/A") -> N/A | R35: =IF(OR($AM35<>"",$Z35<>"",$AC35<>""),"YES","NO") -> NO | S35: =IF(COUNTIF(I35:R35,"NO")=0,"YES","NO") -> NO | AJ35: 8HTV2-CT | AK35: 16.3 m m | AL35: Levy Ostrup
A36: EHT Trace | B36: 29103-ET-PG1903-1-1 | C36: 29103-ET-PG1903-1 | D36: HTC-12 / CB-12 | E36: 29103-PG-1903 | F36: 29103-65R-ET-PG1903-01-01 | G36: 13.1 | H36: 29103-ET-PG1903-1-1.pdf | I36: =IF($H36<>"","YES","NO") -> YES | J36: =IF(N($T36)>0,"YES","NO") -> NO | K36: =IF(OR($A36="EHT Trace"),IF(AND($U36<>"",$V36<>""),"YES","NO"),"N/A") -> NO | L36: =IF(OR($A36="EHT Trace"),IF(AND($X36<>"",$Y36<>""),"YES","NO"),"N/A") -> NO | M36: =IF(OR($A36="EHT Trace"),IF(AND($AA36<>"",$AB36<>""),"YES","NO"),"N/A") -> NO | N36: =IF(OR($A36="Power Cable"),IF(AND($AD36<>""),"YES","NO"),"N/A") -> N/A | O36: =IF(OR($A36="Power Cable",$A36="RTD Cable",$A36="Fieldbus Cable"),IF(AND($AE36<>""),"YES","NO"),"N/A") -> N/A | P36: =IF(OR($A36="RTD"),IF(AND($AH36<>""),"YES","NO"),"N/A") -> N/A | Q36: =IF(OR($A36="RTD"),IF(AND($AI36<>""),"YES","NO"),"N/A") -> N/A | R36: =IF(OR($AM36<>"",$Z36<>"",$AC36<>""),"YES","NO") -> NO | S36: =IF(COUNTIF(I36:R36,"NO")=0,"YES","NO") -> NO | AJ36: 10HTV2-CT | AK36: 54.1 m m | AL36: Levy Ostrup
A37: EHT Trace | B37: 29103-ET-ST0001-1-1 | C37: 29103-ET-ST0001-1 | D37: HTC-14 / CB-14 | E37: 29103-ST-0001 | F37: 29103-65R-ET-ST0001-01-01 | G37: 13.1 | H37: 29103-ET-ST0001-1-1.pdf | I37: =IF($H37<>"","YES","NO") -> YES | J37: =IF(N($T37)>0,"YES","NO") -> NO | K37: =IF(OR($A37="EHT Trace"),IF(AND($U37<>"",$V37<>""),"YES","NO"),"N/A") -> NO | L37: =IF(OR($A37="EHT Trace"),IF(AND($X37<>"",$Y37<>""),"YES","NO"),"N/A") -> NO | M37: =IF(OR($A37="EHT Trace"),IF(AND($AA37<>"",$AB37<>""),"YES","NO"),"N/A") -> NO | N37: =IF(OR($A37="Power Cable"),IF(AND($AD37<>""),"YES","NO"),"N/A") -> N/A | O37: =IF(OR($A37="Power Cable",$A37="RTD Cable",$A37="Fieldbus Cable"),IF(AND($AE37<>""),"YES","NO"),"N/A") -> N/A | P37: =IF(OR($A37="RTD"),IF(AND($AH37<>""),"YES","NO"),"N/A") -> N/A | Q37: =IF(OR($A37="RTD"),IF(AND($AI37<>""),"YES","NO"),"N/A") -> N/A | R37: =IF(OR($AM37<>"",$Z37<>"",$AC37<>""),"YES","NO") -> NO | S37: =IF(COUNTIF(I37:R37,"NO")=0,"YES","NO") -> NO | AJ37: D/32SA2275/24.1M/352/277/1.2M/LS23A/X/N12 | AK37: 24.1 m m | AL37: Levy Ostrup
A38: EHT Trace | B38: 29103-ET-ST0003-1-1 | C38: 29103-ET-ST0003-1 | D38: 29103-AMB-016 | E38: 29103-V-0001, 29103-ST-0003 | F38: 29103-65R-ET-ST0003-01-01 | G38: 13.1 | H38: 29103-ET-ST0003-1-1.pdf | I38: =IF($H38<>"","YES","NO") -> YES | J38: =IF(N($T38)>0,"YES","NO") -> NO | K38: =IF(OR($A38="EHT Trace"),IF(AND($U38<>"",$V38<>""),"YES","NO"),"N/A") -> NO | L38: =IF(OR($A38="EHT Trace"),IF(AND($X38<>"",$Y38<>""),"YES","NO"),"N/A") -> NO | M38: =IF(OR($A38="EHT Trace"),IF(AND($AA38<>"",$AB38<>""),"YES","NO"),"N/A") -> NO | N38: =IF(OR($A38="Power Cable"),IF(AND($AD38<>""),"YES","NO"),"N/A") -> N/A | O38: =IF(OR($A38="Power Cable",$A38="RTD Cable",$A38="Fieldbus Cable"),IF(AND($AE38<>""),"YES","NO"),"N/A") -> N/A | P38: =IF(OR($A38="RTD"),IF(AND($AH38<>""),"YES","NO"),"N/A") -> N/A | Q38: =IF(OR($A38="RTD"),IF(AND($AI38<>""),"YES","NO"),"N/A") -> N/A | R38: =IF(OR($AM38<>"",$Z38<>"",$AC38<>""),"YES","NO") -> NO | S38: =IF(COUNTIF(I38:R38,"NO")=0,"YES","NO") -> NO | AJ38: 5HTV2-CT | AK38: 10.2 m m | AL38: Levy Ostrup
A39: EHT Trace | B39: 29103-ET-ST1816-1-1 | C39: 29103-ET-ST1816-1 | D39: 29103-AMB-016 | E39: 29103-ST-1817, 29103-ST-1816, 29103-ST-0002 | F39: 29103-65R-ET-ST1816-01-01 | G39: 13.1 | H39: 29103-ET-ST1816-1-1.pdf | I39: =IF($H39<>"","YES","NO") -> YES | J39: =IF(N($T39)>0,"YES","NO") -> NO | K39: =IF(OR($A39="EHT Trace"),IF(AND($U39<>"",$V39<>""),"YES","NO"),"N/A") -> NO | L39: =IF(OR($A39="EHT Trace"),IF(AND($X39<>"",$Y39<>""),"YES","NO"),"N/A") -> NO | M39: =IF(OR($A39="EHT Trace"),IF(AND($AA39<>"",$AB39<>""),"YES","NO"),"N/A") -> NO | N39: =IF(OR($A39="Power Cable"),IF(AND($AD39<>""),"YES","NO"),"N/A") -> N/A | O39: =IF(OR($A39="Power Cable",$A39="RTD Cable",$A39="Fieldbus Cable"),IF(AND($AE39<>""),"YES","NO"),"N/A") -> N/A | P39: =IF(OR($A39="RTD"),IF(AND($AH39<>""),"YES","NO"),"N/A") -> N/A | Q39: =IF(OR($A39="RTD"),IF(AND($AI39<>""),"YES","NO"),"N/A") -> N/A | R39: =IF(OR($AM39<>"",$Z39<>"",$AC39<>""),"YES","NO") -> NO | S39: =IF(COUNTIF(I39:R39,"NO")=0,"YES","NO") -> NO | AJ39: 5HTV2-CT | AK39: 34.2 m m | AL39: Levy Ostrup
A40: EHT Trace | B40: 29103-ET-ST1816-1-2 | C40: 29103-ET-ST1816-1 | D40: 29103-AMB-016 | E40: 29103-ST-1818, 29103-ST-1816 | F40: 29103-65R-ET-ST1816-01-01 | G40: 13.1 | H40: 29103-ET-ST1816-1-2.pdf | I40: =IF($H40<>"","YES","NO") -> YES | J40: =IF(N($T40)>0,"YES","NO") -> NO | K40: =IF(OR($A40="EHT Trace"),IF(AND($U40<>"",$V40<>""),"YES","NO"),"N/A") -> NO | L40: =IF(OR($A40="EHT Trace"),IF(AND($X40<>"",$Y40<>""),"YES","NO"),"N/A") -> NO | M40: =IF(OR($A40="EHT Trace"),IF(AND($AA40<>"",$AB40<>""),"YES","NO"),"N/A") -> NO | N40: =IF(OR($A40="Power Cable"),IF(AND($AD40<>""),"YES","NO"),"N/A") -> N/A | O40: =IF(OR($A40="Power Cable",$A40="RTD Cable",$A40="Fieldbus Cable"),IF(AND($AE40<>""),"YES","NO"),"N/A") -> N/A | P40: =IF(OR($A40="RTD"),IF(AND($AH40<>""),"YES","NO"),"N/A") -> N/A | Q40: =IF(OR($A40="RTD"),IF(AND($AI40<>""),"YES","NO"),"N/A") -> N/A | R40: =IF(OR($AM40<>"",$Z40<>"",$AC40<>""),"YES","NO") -> NO | S40: =IF(COUNTIF(I40:R40,"NO")=0,"YES","NO") -> NO | AJ40: 5HTV2-CT | AK40: 27.1 m m | AL40: Levy Ostrup
A41: EHT Trace | B41: 29103-ET-V1900-1-1 | C41: 29103-ET-V1900-1 | D41: HTC-17 / CB-17 | E41: 29103-V-1900 | F41: 29103-65R-ET-V1900-01-01 | G41: 13.1 | H41: 29103-ET-V1900-1-1.pdf | I41: =IF($H41<>"","YES","NO") -> YES | J41: =IF(N($T41)>0,"YES","NO") -> NO | K41: =IF(OR($A41="EHT Trace"),IF(AND($U41<>"",$V41<>""),"YES","NO"),"N/A") -> NO | L41: =IF(OR($A41="EHT Trace"),IF(AND($X41<>"",$Y41<>""),"YES","NO"),"N/A") -> NO | M41: =IF(OR($A41="EHT Trace"),IF(AND($AA41<>"",$AB41<>""),"YES","NO"),"N/A") -> NO | N41: =IF(OR($A41="Power Cable"),IF(AND($AD41<>""),"YES","NO"),"N/A") -> N/A | O41: =IF(OR($A41="Power Cable",$A41="RTD Cable",$A41="Fieldbus Cable"),IF(AND($AE41<>""),"YES","NO"),"N/A") -> N/A | P41: =IF(OR($A41="RTD"),IF(AND($AH41<>""),"YES","NO"),"N/A") -> N/A | Q41: =IF(OR($A41="RTD"),IF(AND($AI41<>""),"YES","NO"),"N/A") -> N/A | R41: =IF(OR($AM41<>"",$Z41<>"",$AC41<>""),"YES","NO") -> NO | S41: =IF(COUNTIF(I41:R41,"NO")=0,"YES","NO") -> NO | AJ41: 20HTV2-CT | AK41: 17.1 m m | AL41: Levy Ostrup
A42: EHT Trace | B42: 29103-ET-V1900-1-2 | C42: 29103-ET-V1900-1 | D42: HTC-17 / CB-17 | E42: 29103-V-1900 | F42: 29103-65R-ET-V1900-01-01 | G42: 13.1 | H42: 29103-ET-V1900-1-2.pdf | I42: =IF($H42<>"","YES","NO") -> YES | J42: =IF(N($T42)>0,"YES","NO") -> NO | K42: =IF(OR($A42="EHT Trace"),IF(AND($U42<>"",$V42<>""),"YES","NO"),"N/A") -> NO | L42: =IF(OR($A42="EHT Trace"),IF(AND($X42<>"",$Y42<>""),"YES","NO"),"N/A") -> NO | M42: =IF(OR($A42="EHT Trace"),IF(AND($AA42<>"",$AB42<>""),"YES","NO"),"N/A") -> NO | N42: =IF(OR($A42="Power Cable"),IF(AND($AD42<>""),"YES","NO"),"N/A") -> N/A | O42: =IF(OR($A42="Power Cable",$A42="RTD Cable",$A42="Fieldbus Cable"),IF(AND($AE42<>""),"YES","NO"),"N/A") -> N/A | P42: =IF(OR($A42="RTD"),IF(AND($AH42<>""),"YES","NO"),"N/A") -> N/A | Q42: =IF(OR($A42="RTD"),IF(AND($AI42<>""),"YES","NO"),"N/A") -> N/A | R42: =IF(OR($AM42<>"",$Z42<>"",$AC42<>""),"YES","NO") -> NO | S42: =IF(COUNTIF(I42:R42,"NO")=0,"YES","NO") -> NO | AJ42: 20HTV2-CT | AK42: 15.2 m m | AL42: Levy Ostrup
A43: EHT Trace | B43: 29209-ET-A001-1-1 | C43: 29209-ET-A001-1 | D43: HTC-29 / CB-29 | E43: 29209-A-001 | F43: 29209-65R-ET-A001-01-01 | G43: 13.1 | H43: 29209-ET-A001-1-1.pdf | I43: =IF($H43<>"","YES","NO") -> YES | J43: =IF(N($T43)>0,"YES","NO") -> NO | K43: =IF(OR($A43="EHT Trace"),IF(AND($U43<>"",$V43<>""),"YES","NO"),"N/A") -> NO | L43: =IF(OR($A43="EHT Trace"),IF(AND($X43<>"",$Y43<>""),"YES","NO"),"N/A") -> NO | M43: =IF(OR($A43="EHT Trace"),IF(AND($AA43<>"",$AB43<>""),"YES","NO"),"N/A") -> NO | N43: =IF(OR($A43="Power Cable"),IF(AND($AD43<>""),"YES","NO"),"N/A") -> N/A | O43: =IF(OR($A43="Power Cable",$A43="RTD Cable",$A43="Fieldbus Cable"),IF(AND($AE43<>""),"YES","NO"),"N/A") -> N/A | P43: =IF(OR($A43="RTD"),IF(AND($AH43<>""),"YES","NO"),"N/A") -> N/A | Q43: =IF(OR($A43="RTD"),IF(AND($AI43<>""),"YES","NO"),"N/A") -> N/A | R43: =IF(OR($AM43<>"",$Z43<>"",$AC43<>""),"YES","NO") -> NO | S43: =IF(COUNTIF(I43:R43,"NO")=0,"YES","NO") -> NO | AJ43: 5HTV2-CT | AK43: 4.9 m m | AL43: Levy Ostrup
A44: EHT Trace | B44: 29209-ET-A001-1-2 | C44: 29209-ET-A001-1 | D44: HTC-29 / CB-29 | E44: 29209-A-001 | F44: 29209-65R-ET-A001-01-01 | G44: 13.1 | H44: 29209-ET-A001-1-2.pdf | I44: =IF($H44<>"","YES","NO") -> YES | J44: =IF(N($T44)>0,"YES","NO") -> NO | K44: =IF(OR($A44="EHT Trace"),IF(AND($U44<>"",$V44<>""),"YES","NO"),"N/A") -> NO | L44: =IF(OR($A44="EHT Trace"),IF(AND($X44<>"",$Y44<>""),"YES","NO"),"N/A") -> NO | M44: =IF(OR($A44="EHT Trace"),IF(AND($AA44<>"",$AB44<>""),"YES","NO"),"N/A") -> NO | N44: =IF(OR($A44="Power Cable"),IF(AND($AD44<>""),"YES","NO"),"N/A") -> N/A | O44: =IF(OR($A44="Power Cable",$A44="RTD Cable",$A44="Fieldbus Cable"),IF(AND($AE44<>""),"YES","NO"),"N/A") -> N/A | P44: =IF(OR($A44="RTD"),IF(AND($AH44<>""),"YES","NO"),"N/A") -> N/A | Q44: =IF(OR($A44="RTD"),IF(AND($AI44<>""),"YES","NO"),"N/A") -> N/A | R44: =IF(OR($AM44<>"",$Z44<>"",$AC44<>""),"YES","NO") -> NO | S44: =IF(COUNTIF(I44:R44,"NO")=0,"YES","NO") -> NO | AJ44: 5HTV2-CT | AK44: 4.9 m m | AL44: Levy Ostrup
... A48: EHT Trace | B48: 29209-ET-P6020-1-1 | C48: 29209-ET-P6020-1 | D48: HTC-23 / CB-23 | E48: 29209-P-6020 | F48: 29209-65R-ET-P6020-01-01 | G48: 13.1 | H48: 29209-ET-P6020-1-1.pdf | I48: =IF($H48<>"","YES","NO") -> YES | J48: =IF(N($T48)>0,"YES","NO") -> NO | K48: =IF(OR($A48="EHT Trace"),IF(AND($U48<>"",$V48<>""),"YES","NO"),"N/A") -> NO | L48: =IF(OR($A48="EHT Trace"),IF(AND($X48<>"",$Y48<>""),"YES","NO"),"N/A") -> NO | M48: =IF(OR($A48="EHT Trace"),IF(AND($AA48<>"",$AB48<>""),"YES","NO"),"N/A") -> NO | N48: =IF(OR($A48="Power Cable"),IF(AND($AD48<>""),"YES","NO"),"N/A") -> N/A | O48: =IF(OR($A48="Power Cable",$A48="RTD Cable",$A48="Fieldbus Cable"),IF(AND($AE48<>""),"YES","NO"),"N/A") -> N/A | P48: =IF(OR($A48="RTD"),IF(AND($AH48<>""),"YES","NO"),"N/A") -> N/A | Q48: =IF(OR($A48="RTD"),IF(AND($AI48<>""),"YES","NO"),"N/A") -> N/A | R48: =IF(OR($AM48<>"",$Z48<>"",$AC48<>""),"YES","NO") -> NO | S48: =IF(COUNTIF(I48:R48,"NO")=0,"YES","NO") -> NO | AJ48: D/32SQ3200/54.9M/1976/277/2.1M/LS23A/X/N12 | AK48: 54.9 m m | AL48: Levy Ostrup
A49: EHT Trace | B49: 29209-ET-P6020-1-2 | C49: 29209-ET-P6020-1 | D49: HTC-23 / CB-23 | E49: 29209-P-6020 | F49: 29209-65R-ET-P6020-01-01 | G49: 13.1 | H49: 29209-ET-P6020-1-2.pdf | I49: =IF($H49<>"","YES","NO") -> YES | J49: =IF(N($T49)>0,"YES","NO") -> NO | K49: =IF(OR($A49="EHT Trace"),IF(AND($U49<>"",$V49<>""),"YES","NO"),"N/A") -> YES | L49: =IF(OR($A49="EHT Trace"),IF(AND($X49<>"",$Y49<>""),"YES","NO"),"N/A") -> NO | M49: =IF(OR($A49="EHT Trace"),IF(AND($AA49<>"",$AB49<>""),"YES","NO"),"N/A") -> NO | N49: =IF(OR($A49="Power Cable"),IF(AND($AD49<>""),"YES","NO"),"N/A") -> N/A | O49: =IF(OR($A49="Power Cable",$A49="RTD Cable",$A49="Fieldbus Cable"),IF(AND($AE49<>""),"YES","NO"),"N/A") -> N/A | P49: =IF(OR($A49="RTD"),IF(AND($AH49<>""),"YES","NO"),"N/A") -> N/A | Q49: =IF(OR($A49="RTD"),IF(AND($AI49<>""),"YES","NO"),"N/A") -> N/A | R49: =IF(OR($AM49<>"",$Z49<>"",$AC49<>""),"YES","NO") -> NO | S49: =IF(COUNTIF(I49:R49,"NO")=0,"YES","NO") -> NO | U49: >2.2 GΩ | V49: 12.6 Ω | W49: 2026-05-17 | AJ49: E/32SQ3100/36.6M/1486/138/2.1M/LS23A/X/N12 | AK49: 36.6 m m | AL49: Levy Ostrup
A50: EHT Trace | B50: 29209-ET-P6020-1-3 | C50: 29209-ET-P6020-1 | D50: HTC-23 / CB-23 | E50: 29209-P-6020 | F50: 29209-65R-ET-P6020-01-01 | G50: 13.1 | H50: 29209-ET-P6020-1-3.pdf | I50: =IF($H50<>"","YES","NO") -> YES | J50: =IF(N($T50)>0,"YES","NO") -> NO | K50: =IF(OR($A50="EHT Trace"),IF(AND($U50<>"",$V50<>""),"YES","NO"),"N/A") -> YES | L50: =IF(OR($A50="EHT Trace"),IF(AND($X50<>"",$Y50<>""),"YES","NO"),"N/A") -> NO | M50: =IF(OR($A50="EHT Trace"),IF(AND($AA50<>"",$AB50<>""),"YES","NO"),"N/A") -> NO | N50: =IF(OR($A50="Power Cable"),IF(AND($AD50<>""),"YES","NO"),"N/A") -> N/A | O50: =IF(OR($A50="Power Cable",$A50="RTD Cable",$A50="Fieldbus Cable"),IF(AND($AE50<>""),"YES","NO"),"N/A") -> N/A | P50: =IF(OR($A50="RTD"),IF(AND($AH50<>""),"YES","NO"),"N/A") -> N/A | Q50: =IF(OR($A50="RTD"),IF(AND($AI50<>""),"YES","NO"),"N/A") -> N/A | R50: =IF(OR($AM50<>"",$Z50<>"",$AC50<>""),"YES","NO") -> NO | S50: =IF(COUNTIF(I50:R50,"NO")=0,"YES","NO") -> NO | U50: >2.2 GΩ | V50: 12.6 Ω | W50: 2026-05-17 | AJ50: D/32SQ3100/36.6M/1486/138/2.1M/LS23A/X/N12 | AK50: 36.6 m m | AL50: Levy Ostrup
A51: EHT Trace | B51: 29209-ET-P6021-1-1 | C51: 29209-ET-P6021-1 | D51: HTC-18 / CB-18 | E51: 29209-P-6021 | F51: 29209-65R-ET-P6021-01-01 | G51: 13.1 | H51: 29209-ET-P6021-1-1.pdf | I51: =IF($H51<>"","YES","NO") -> YES | J51: =IF(N($T51)>0,"YES","NO") -> NO | K51: =IF(OR($A51="EHT Trace"),IF(AND($U51<>"",$V51<>""),"YES","NO"),"N/A") -> NO | L51: =IF(OR($A51="EHT Trace"),IF(AND($X51<>"",$Y51<>""),"YES","NO"),"N/A") -> NO | M51: =IF(OR($A51="EHT Trace"),IF(AND($AA51<>"",$AB51<>""),"YES","NO"),"N/A") -> NO | N51: =IF(OR($A51="Power Cable"),IF(AND($AD51<>""),"YES","NO"),"N/A") -> N/A | O51: =IF(OR($A51="Power Cable",$A51="RTD Cable",$A51="Fieldbus Cable"),IF(AND($AE51<>""),"YES","NO"),"N/A") -> N/A | P51: =IF(OR($A51="RTD"),IF(AND($AH51<>""),"YES","NO"),"N/A") -> N/A | Q51: =IF(OR($A51="RTD"),IF(AND($AI51<>""),"YES","NO"),"N/A") -> N/A | R51: =IF(OR($AM51<>"",$Z51<>"",$AC51<>""),"YES","NO") -> NO | S51: =IF(COUNTIF(I51:R51,"NO")=0,"YES","NO") -> NO | AJ51: D/32SQ3200/54.9M/1976/277/2.1M/LS23A/X/N12 | AK51: 54.9 m m | AL51: Levy Ostrup
A52: EHT Trace | B52: 29209-ET-P6021-1-2 | C52: 29209-ET-P6021-1 | D52: HTC-18 / CB-18 | E52: 29209-P-6021 | F52: 29209-65R-ET-P6021-01-01 | G52: 13.1 | H52: 29209-ET-P6021-1-2.pdf | I52: =IF($H52<>"","YES","NO") -> YES | J52: =IF(N($T52)>0,"YES","NO") -> NO | K52: =IF(OR($A52="EHT Trace"),IF(AND($U52<>"",$V52<>""),"YES","NO"),"N/A") -> NO | L52: =IF(OR($A52="EHT Trace"),IF(AND($X52<>"",$Y52<>""),"YES","NO"),"N/A") -> NO | M52: =IF(OR($A52="EHT Trace"),IF(AND($AA52<>"",$AB52<>""),"YES","NO"),"N/A") -> NO | N52: =IF(OR($A52="Power Cable"),IF(AND($AD52<>""),"YES","NO"),"N/A") -> N/A | O52: =IF(OR($A52="Power Cable",$A52="RTD Cable",$A52="Fieldbus Cable"),IF(AND($AE52<>""),"YES","NO"),"N/A") -> N/A | P52: =IF(OR($A52="RTD"),IF(AND($AH52<>""),"YES","NO"),"N/A") -> N/A | Q52: =IF(OR($A52="RTD"),IF(AND($AI52<>""),"YES","NO"),"N/A") -> N/A | R52: =IF(OR($AM52<>"",$Z52<>"",$AC52<>""),"YES","NO") -> NO | S52: =IF(COUNTIF(I52:R52,"NO")=0,"YES","NO") -> NO | AJ52: E/32SQ3100/36.6M/1486/138/2.1M/LS23A/X/N12 | AK52: 36.6 m m | AL52: Levy Ostrup
A53: EHT Trace | B53: 29209-ET-P6021-1-3 | C53: 29209-ET-P6021-1 | D53: HTC-18 / CB-18 | E53: 29209-P-6021 | F53: 29209-65R-ET-P6021-01-01 | G53: 13.1 | H53: 29209-ET-P6021-1-3.pdf | I53: =IF($H53<>"","YES","NO") -> YES | J53: =IF(N($T53)>0,"YES","NO") -> NO | K53: =IF(OR($A53="EHT Trace"),IF(AND($U53<>"",$V53<>""),"YES","NO"),"N/A") -> NO | L53: =IF(OR($A53="EHT Trace"),IF(AND($X53<>"",$Y53<>""),"YES","NO"),"N/A") -> NO | M53: =IF(OR($A53="EHT Trace"),IF(AND($AA53<>"",$AB53<>""),"YES","NO"),"N/A") -> NO | N53: =IF(OR($A53="Power Cable"),IF(AND($AD53<>""),"YES","NO"),"N/A") -> N/A | O53: =IF(OR($A53="Power Cable",$A53="RTD Cable",$A53="Fieldbus Cable"),IF(AND($AE53<>""),"YES","NO"),"N/A") -> N/A | P53: =IF(OR($A53="RTD"),IF(AND($AH53<>""),"YES","NO"),"N/A") -> N/A | Q53: =IF(OR($A53="RTD"),IF(AND($AI53<>""),"YES","NO"),"N/A") -> N/A | R53: =IF(OR($AM53<>"",$Z53<>"",$AC53<>""),"YES","NO") -> NO | S53: =IF(COUNTIF(I53:R53,"NO")=0,"YES","NO") -> NO | AJ53: D/32SQ3100/36.6M/1486/138/2.1M/LS23A/X/N12 | AK53: 36.6 m m | AL53: Levy Ostrup
A54: EHT Trace | B54: 29209-ET-P6022-1-1 | C54: 29209-ET-P6022-1 | D54: HTC-21 / CB-21 | E54: 29209-P-6022 | F54: 29209-65R-ET-P6022-01-01 | G54: 13.1 | H54: 29209-ET-P6022-1-1.pdf | I54: =IF($H54<>"","YES","NO") -> YES | J54: =IF(N($T54)>0,"YES","NO") -> NO | K54: =IF(OR($A54="EHT Trace"),IF(AND($U54<>"",$V54<>""),"YES","NO"),"N/A") -> NO | L54: =IF(OR($A54="EHT Trace"),IF(AND($X54<>"",$Y54<>""),"YES","NO"),"N/A") -> NO | M54: =IF(OR($A54="EHT Trace"),IF(AND($AA54<>"",$AB54<>""),"YES","NO"),"N/A") -> NO | N54: =IF(OR($A54="Power Cable"),IF(AND($AD54<>""),"YES","NO"),"N/A") -> N/A | O54: =IF(OR($A54="Power Cable",$A54="RTD Cable",$A54="Fieldbus Cable"),IF(AND($AE54<>""),"YES","NO"),"N/A") -> N/A | P54: =IF(OR($A54="RTD"),IF(AND($AH54<>""),"YES","NO"),"N/A") -> N/A | Q54: =IF(OR($A54="RTD"),IF(AND($AI54<>""),"YES","NO"),"N/A") -> N/A | R54: =IF(OR($AM54<>"",$Z54<>"",$AC54<>""),"YES","NO") -> NO | S54: =IF(COUNTIF(I54:R54,"NO")=0,"YES","NO") -> NO | AJ54: D/32SQ3293/42.6M/1742/277/1.2M/LS23A/X/N12 | AK54: 42.6 m m | AL54: Levy Ostrup
A55: EHT Trace | B55: 29209-ET-P6022-1-2 | C55: 29209-ET-P6022-1 | D55: HTC-21 / CB-21 | E55: 29209-P-6022 | F55: 29209-65R-ET-P6022-01-01 | G55: 13.1 | H55: 29209-ET-P6022-1-2.pdf | I55: =IF($H55<>"","YES","NO") -> YES | J55: =IF(N($T55)>0,"YES","NO") -> NO | K55: =IF(OR($A55="EHT Trace"),IF(AND($U55<>"",$V55<>""),"YES","NO"),"N/A") -> NO | L55: =IF(OR($A55="EHT Trace"),IF(AND($X55<>"",$Y55<>""),"YES","NO"),"N/A") -> NO | M55: =IF(OR($A55="EHT Trace"),IF(AND($AA55<>"",$AB55<>""),"YES","NO"),"N/A") -> NO | N55: =IF(OR($A55="Power Cable"),IF(AND($AD55<>""),"YES","NO"),"N/A") -> N/A | O55: =IF(OR($A55="Power Cable",$A55="RTD Cable",$A55="Fieldbus Cable"),IF(AND($AE55<>""),"YES","NO"),"N/A") -> N/A | P55: =IF(OR($A55="RTD"),IF(AND($AH55<>""),"YES","NO"),"N/A") -> N/A | Q55: =IF(OR($A55="RTD"),IF(AND($AI55<>""),"YES","NO"),"N/A") -> N/A | R55: =IF(OR($AM55<>"",$Z55<>"",$AC55<>""),"YES","NO") -> NO | S55: =IF(COUNTIF(I55:R55,"NO")=0,"YES","NO") -> NO | AJ55: E/32SQ3100/38.2M/1429/138/1.2M/LS23A/X/N12 | AK55: 38.2 m m | AL55: Levy Ostrup
...

Sheet 29103-HTP-100
A1: 29103-HTP-100
I3: CHECKSHEETS | T3: TEST RESULTS
A4: Type | B4: Tag | C4: Circuit | D4: Controller | E4: System | F4: ISO / Dwg | G4: Form | H4: File | I4: ITR | J4: Visual | K4: Rec. Megger | L4: Pre-Insul Megger | M4: Post-Insul Megger | N4: Cable IR | O4: Cable Cont. | P4: RTD Pre | Q4: RTD Post | R4: Dated | S4: Complete | T4: Visual Initials | U4: Rec. IR | V4: Rec. Cont. | W4: Rec. Date | X4: Pre IR | Y4: Pre Cont. | Z4: Pre Date | AA4: Post IR | AB4: Post Cont. | AC4: Post Date | AD4: Cable IR | AE4: Cable Cont. | AF4: Meter | AG4: RTD Ω | AH4: RTD Pre (S/C/Com) | AI4: RTD Post (S/C/Com) | AJ4: Part # / Cable | AK4: Length / Size | AL4: Inspected By | AM4: Date | AN4: Remarks
