Workbook
Name L_ansi_rating: Lists!$G$1:$G$7
Name L_asme_code: Lists!$A$1:$A$2
Name L_body_style: Lists!$H$1:$H$2
Name L_command_signal_type: Lists!$M$1:$M$2
Name L_fail_position: Lists!$L$1:$L$3
Name L_local_display: Lists!$B$1:$B$2
Name L_signal_type: Lists!$I$1:$I$5
Name L_system_results: Lists!$C$1:$C$3
Name L_travel_unit: Lists!$E$1:$E$2
Name L_valve_class: Lists!$F$1:$F$6
Name L_valve_stem_type: Lists!$K$1:$K$5
Name L_valve_type: Lists!$D$1:$D$5
Name L_verified_by: Lists!$J$1:$J$2

Sheet Dashboard
B2: K1B Well Pad – Equipment Inspection Tracker
B3: Transmitter Inspection & Test Records + Pneumatically Actuated Valve Check Records
B5: GO TO: | C5: =HYPERLINK("#'Transmitter Log'!A1","Transmitter Log") | D5: =HYPERLINK("#'Transmitter Index'!A1","Transmitter Index") | E5: =HYPERLINK("#'Valve Log'!A1","Valve Log") | F5: =HYPERLINK("#'Valve Index'!A1","Valve Index") | G5: =HYPERLINK("#Instructions!A1","Instructions")
B8: TRANSMITTERS LOGGED | D8: VALVES LOGGED | F8: MARKED READY (Y) | H8: TOTAL EQUIPMENT
B9: =COUNTIF('Transmitter Log 100'!F5:F304,"?*") | D9: =COUNTIF('Valve Log 100'!I5:I304,"?*") | F9: =COUNTIF('Transmitter Log 100'!A5:A304,"Y")+COUNTIF('Valve Log 100'!A5:A304,"Y") | H9: =COUNTIF('Transmitter Log 100'!F5:F304,"?*")+COUNTIF('Valve Log 100'!I5:I304,"?*")
B14: SYSTEM BREAKDOWN
B15: 100 Series
B16: System | C16: Transmitters | D16: Valves | E16: Total
B17: STEAM | C17: =COUNTIF('Transmitter Log 100'!H5:H304,"STEAM") | D17: =COUNTIF('Valve Log 100'!F5:F304,"STEAM") | E17: =C17+D17
B18: NATURAL GAS | C18: =COUNTIF('Transmitter Log 100'!H5:H304,"NATURAL GAS") | D18: =COUNTIF('Valve Log 100'!F5:F304,"NATURAL GAS") | E18: =C18+D18
B19: PRODUCED EMULSION | C19: =COUNTIF('Transmitter Log 100'!H5:H304,"PRODUCED EMULSION") | D19: =COUNTIF('Valve Log 100'!F5:F304,"PRODUCED EMULSION") | E19: =C19+D19
B21: 200 Series
B22: System | C22: Transmitters | D22: Valves | E22: Total
B23: STEAM | C23: =COUNTIF('Transmitter Log 200'!H11:H310,"STEAM") | D23: =COUNTIF('Valve Log 200'!F11:F310,"STEAM") | E23: =C23+D23
B24: NATURAL GAS | C24: =COUNTIF('Transmitter Log 200'!H11:H310,"NATURAL GAS") | D24: =COUNTIF('Valve Log 200'!F11:F310,"NATURAL GAS") | E24: =C24+D24
B25: PRODUCED EMULSION | C25: =COUNTIF('Transmitter Log 200'!H11:H310,"PRODUCED EMULSION") | D25: =COUNTIF('Valve Log 200'!F11:F310,"PRODUCED EMULSION") | E25: =C25+D25
B26: Serial # Missing
B29: QUICK TIPS
B30: • Enter data in the Log tabs (grouped by section, dropdown columns are restricted to valid choices).
B31: • Set column A ("Export to PDF (Y/N)") to Y on rows you want turned into filled PDFs.
B32: • Use the Index tabs for a condensed view - click a row number to jump straight to it in the full log.
B33: • Run the matching export script (export_to_pdf.py or export_valve_to_pdf.py) to generate PDFs.
B34: • See the Instructions tab for full details, including the PDF export command-line options.

Sheet Lists
A1: Y | B1: Yes | C1: Pass | D1: ESDV | E1: Inch | F1: I | G1: 150 | H1: Flanged | I1: 4-20 mA / HART | J1: IESL | K1: Sliding Stem | L1: Valve Fails Open | M1: mA
A2: N | B2: No | C2: Fail | D2: FCV | E2: Metric | F2: II | G2: 300 | H2: Threaded | I2: Fieldbus | J2: Other | K2: Rotary | L2: Valve Fails Closed | M2: %
C3: N/A | D3: LCV | F3: III | G3: 600 | I3: Wireless | K3: Quarter Turn | L3: Valve Fails Last
D4: PCV | F4: IV | G4: 900 | I4: Modbus | K4: Throttle
D5: Other | F5: V | G5: 1200 | I5: Pneumatic | K5: Snap Acting
F6: VI | G6: 1500
G7: 2500

Sheet Valve Log 100
A1: =HYPERLINK("#Dashboard!A1","<< Dashboard")
A2: Control | B2: Header | M2: General Description | AF2: Commissioning Inspection | BB2: Functional Verification Activities | BM2: Positioner / Valve Travel Indication | CE2: Calibration & Configuration Test Equipment Used | CI2: Comments | CJ2: Sign-Off
A3: Export to PDF (Y/N) | B3: Customer Name | C3: Project Name | D3: Contract # | E3: Location | F3: System | G3: P&ID # | H3: Line # | I3: Equip # | J3: Unit # | K3: Valve Type | L3: Valve Type - Other (specify) | M3: Actuator - Serial # | N3: Actuator - Model # | O3: Trim - Plug | P3: Trim - Seat | Q3: Valve - Serial # | R3: Valve - Model # | S3: Travel - Unit | T3: Travel - Value | U3: Positioner - Serial # | V3: Positioner - Model # | W3: Class (ANSI Leakage Class) | X3: ANSI Rating | Y3: Position Limit - Serial # | Z3: Position Limit - Model # | AA3: ANSI Rating - Size | AB3: Body Style | AC3: Solenoid - Serial # | AD3: Solenoid - Model # | AE3: CRN# | AF3: Signal Type | AG3: Commissioning Tag # | AH3: Voltage | AI3: Fuse Rating | AJ3: Inst. Air Pressure | AK3: Bad I/O | AL3: Verify Device & Screen Match | AM3: SS Device Tag | AN3: SS Cable Tag | AO3: Calibration Tag | AP3: Wire Tagged | AQ3: Cable & Fittings Inspected | AR3: Adequate Service Loop | AS3: Polarity Correct & Wire Tug | AT3: Heat Traced | AU3: Insulated | AV3: Tubing & Fittings Inspected | AW3: Conforms to Install | AX3: Conforms to P&ID | AY3: Installed By | AZ3: Verified By | BA3: ASME Code | BB3: 1. Blow Down Air Supply at Header, Open and Drain Instrument Regulator (initials, or N/A) | BC3: 2. Valve is Sliding Stem: Rotary: Quarter Turn: Throttle: Snap Acting (initials, or N/A) | BD3: 3. Verify Fail Position: Valve Fails Open / Valve Fails Closed / Valve Fails Last (initials, or N/A) | BE3: 4. Verify Positioner Command Signals: mA / % (initials, or N/A) | BF3: 5. Valve and Actuator Strokes Smoothly on Command From DCS/PLC (initials, or N/A) | BG3: 6. Verify Open and Close Limit Switches Function and are Displayed Correctly on DCS/PLC (initials, or N/A) | BH3: 7. Verify Solenoid Trip and Valve Strokes to Fail Position (initials, or N/A) | BI3: 8. Verify Positioner is Returned to IN SERVICE (initials, or N/A) | BJ3: Valve is Sliding Stem / Type | BK3: Verify Fail Position | BL3: Verify Positioner Command Signals | BM3: Valve Position @ 0% (up) | BN3: Valve Position @ 25% (up) | BO3: Valve Position @ 50% (up) | BP3: Valve Position @ 75% (up) | BQ3: Valve Position @ 100% | BR3: Valve Position @ 75% (down) | BS3: Valve Position @ 50% (down) | BT3: Valve Position @ 25% (down) | BU3: Valve Position @ 0% (down) | BV3: mA Input @ 0% (up) | BW3: mA Input @ 25% (up) | BX3: mA Input @ 50% (up) | BY3: mA Input @ 75% (up) | BZ3: mA Input @ 100% | CA3: mA Input @ 75% (down) | CB3: mA Input @ 50% (down) | CC3: mA Input @ 25% (down) | CD3: mA Input @ 0% (down) | CE3: Test Equipment - Make | CF3: Test Equipment - Model | CG3: Test Equipment - Serial# | CH3: Test Equipment - Calibration Date | CI3: Comments | CJ3: YANDA QC Representative - Name | CK3: YANDA Commissioning Representative - Name | CL3: YANDA QC Representative - Date
A4: N | G4: 29103-25J-106-01 | H4: 29103-16"-ST-1800-DASB0-90H | I4: 29103-PV-1200 | K4: PCV | M4: N/A | N4: 51 | O4: CA6NM SS/Nitrided | P4: A487 gr CA6NM HF | Q4: N/A | R4: N/A | S4: Inch | T4: 3 | U4: N/A | V4: SVI3 | W4: IV | X4: 1500 | Y4: N/A | Z4: N/A | AA4: 12" | AB4: Flanged | AC4: N/A | AD4: N/A | AE4: 0C18929.52 | CE4: EMERSON | CF4: TREX | CG4: 210100082367 | CH4: '2026-07-31
C5: K1B WELL PAD PROJECT | D5: CA23007 | E5: KINOSIS K1B | F5: STEAM | G5: 29103-25J-106-01 | H5: 29103-16"-ST-1800-DASB0-90H | I5: 29103-PV-1200 | K5: PCV | M5: S-26-019797 | N5: 51 | O5: CA6NM SS/Nitrided | P5: A487 gr CA6NM HF | Q5: N/A | R5: 41000 | S5: Inch | T5: 3" | U5: F005382540 | V5: SVI3 | W5: IV | X5: 1500 | Y5: N/A | Z5: N/A | AA5: 12 | AB5: Flanged | AC5: N/A | AD5: N/A | AE5: 0C18929.52 | CE5: EMERSON | CF5: TREX | CG5: 210100082367 | CH5: '2026-07-31 | CJ5: Levy Ostrup
C6: K1B WELL PAD PROJECT | D6: CA23007 | E6: KINOSIS K1B | F6: STEAM | G6: 29103-25J-111-01 | H6: 29103-6"-ST-1102-BASB0-64H | I6: 29103-FV-1011 | K6: FCV | M6: 1000383587 | N6: PDA200 | O6: 5CB TC | P6: TC c/w S17400 carrier | Q6: 1000383579 | R6: P3E HT | S6: Inch | T6: 4" | U6: F005340804 | V6: DVC-6200 | W6: V | X6: 900 | Y6: N/A | Z6: N/A | AA6: 2.15 | AB6: Flanged | AC6: N/A | AD6: N/A | AE6: 0C00070.2 | CE6: EMERSON | CF6: TREX | CG6: 210100082367 | CH6: '2026-07-31 | CJ6: Levy Ostrup
C7: K1B WELL PAD PROJECT | D7: CA23007 | E7: KINOSIS K1B | F7: STEAM | G7: 29103-25J-111-01 | H7: 29103-3"-ST-1101-DASB0-64H | I7: 29103-FV-1012 | K7: FCV | M7: 1000383583 | N7: PDA200 | O7: 5CB TC | P7: TC c/w S17400 carrier | Q7: 1000389735 | R7: P25E HT | S7: Inch | T7: 3" | U7: F005340807 | V7: DVC-6200 | W7: V | X7: 900 | Y7: N/A | Z7: N/A | AA7: 1.5 | AB7: Flanged | AC7: N/A | AD7: N/A | AE7: 0C00070.2 | CE7: EMERSON | CF7: TREX | CG7: 210100082367 | CH7: '2026-07-31 | CJ7: Levy Ostrup
C8: K1B WELL PAD PROJECT | D8: CA23007 | E8: KINOSIS K1B | F8: STEAM | G8: 29103-25J-121-01 | H8: 29103-6"-ST-1202-DASB0-64H | I8: 29103-FV-1021 | K8: FCV | M8: 1000383602 | N8: PDA200 | O8: 5CB TC | P8: TC c/w S17400 carrier | Q8: 1000383595 | R8: P3E HT | S8: Inch | T8: 4" | U8: F005340829 | V8: DVC-6200 | W8: V | X8: 900 | Y8: N/A | Z8: N/A | AA8: 2.15 | AB8: Flanged | AC8: N/A | AD8: N/A | AE8: 0C00070.2 | CE8: EMERSON | CF8: TREX | CG8: 210100082367 | CH8: '2026-07-31 | CJ8: Levy Ostrup
C9: K1B WELL PAD PROJECT | D9: CA23007 | E9: KINOSIS K1B | F9: STEAM | G9: 29103-25J-121-01 | H9: 29103-3"-ST-1201-DASB0-64H | I9: 29103-FV-1022 | K9: FCV | M9: 1000383533 | N9: PDA200 | O9: 5CB TC | P9: TC c/c S17400 carrier | Q9: 1000389751 | R9: P25E HT | S9: Inch | T9: 3" | U9: F005209238 | V9: DVC-6200 | W9: V | X9: 900 | Y9: N/A | Z9: N/A | AA9: 1.5 | AB9: Flanged | AC9: N/A | AD9: N/A | AE9: 0C00070.2 | CE9: EMERSON | CF9: TREX | CG9: 210100082367 | CH9: '2026-07-31 | CJ9: Levy Ostrup
C10: K1B WELL PAD PROJECT | D10: CA23007 | E10: KINOSIS K1B | F10: STEAM | G10: 29103-25J-131-01 | H10: 29103-6"-ST-1302-DASB0-64H | I10: 29103-FV-1031 | K10: FCV | M10: 1000383588 | N10: PDA200 | O10: 5CB TC | P10: TC c/w S17400 carrier | Q10: 1000383580 | R10: P3E HT | S10: Inch | T10: 4" | U10: F005340815 | V10: DVC-6200 | W10: V | X10: 900 | Y10: N/A | Z10: N/A | AA10: 2.15 | AB10: Flanged | AC10: N/A | AD10: N/A | AE10: 0C00070.2 | CE10: EMERSON | CF10: TREX | CG10: 210100082367 | CH10: '2026-07-31 | CJ10: Levy Ostrup
C11: K1B WELL PAD PROJECT | D11: CA23007 | E11: KINOSIS K1B | F11: STEAM | G11: 29103-25J-131-01 | H11: 29103-3"-ST-1301-DASB0-64H | I11: 29103-FV-1032 | K11: FCV | M11: 1000383564 | N11: PDA200 | O11: 5CB TC | P11: TC c/w S17400 carrier | Q11: 1000389736 | R11: P25E HT | S11: Inch | T11: 3" | U11: F005340816 | V11: DVC-6200 | W11: V | X11: 900 | Y11: N/A | Z11: N/A | AA11: 1.5 | AB11: Flanged | AC11: N/A | AD11: N/A | AE11: 0C00070.2 | CE11: EMERSON | CF11: TREX | CG11: 210100082367 | CH11: '2026-07-31 | CJ11: Levy Ostrup
C12: K1B WELL PAD PROJECT | D12: CA23007 | E12: KINOSIS K1B | F12: STEAM | G12: 29103-25J-141-01 | H12: 29103-6"-ST-1402-DASB0-64H | I12: 29103-FV-1041 | K12: FCV | M12: 1000383603 | N12: PDA200 | O12: 5CB TC | P12: TC c/w S17400 carrier | Q12: 1000383596 | R12: P3E HT | S12: Inch | T12: 4" | U12: F005340813 | V12: DVC-6200 | W12: V | X12: 900 | Y12: N/A | Z12: N/A | AA12: 2.15 | AB12: Flanged | AC12: N/A | AD12: N/A | AE12: 0C00070.2 | CE12: EMERSON | CF12: TREX | CG12: 210100082367 | CH12: '2026-07-31 | CJ12: Levy Ostrup
C13: K1B WELL PAD PROJECT | D13: CA23007 | E13: KINOSIS K1B | F13: STEAM | G13: 29103-25J-141-01 | H13: 29103-3"-ST-1401-DASB0-64H | I13: 29103-FV-1042 | K13: FCV | M13: 1000383534 | N13: PDA200 | O13: 5CB TC | P13: TC c/w S17400 carrier | Q13: 1000389752 | R13: P25E HT | S13: Inch | T13: 3" | U13: F005209236 | V13: DVC-6200 | W13: V | X13: 900 | Y13: N/A | Z13: N/A | AA13: 1.5 | AB13: Flanged | AC13: N/A | AD13: N/A | AE13: 0C00070.2 | CE13: EMERSON | CF13: TREX | CG13: 210100082367 | CH13: '2026-07-31 | CJ13: Levy Ostrup
C14: K1B WELL PAD PROJECT | D14: CA23007 | E14: KINOSIS K1B | F14: STEAM | G14: 29103-25J-151-01 | H14: 29103-6"-ST-1502-DASB0-64H | I14: 29103-FV-1051 | K14: FCV | M14: 1000383589 | N14: PDA200 | O14: 5CB TC | P14: TC c/w S17400 carrier | Q14: 1000383581 | R14: P3E HT | S14: Inch | T14: 4" | U14: F005340836 | V14: DVC-6200 | W14: V | X14: 900 | Y14: N/A | Z14: N/A | AA14: 2.15 | AB14: Flanged | AC14: N/A | AD14: N/A | AE14: 0C00070.2 | CE14: EMERSON | CF14: TREX | CG14: 210100082367 | CH14: '2026-07-31 | CJ14: Levy Ostrup
C15: K1B WELL PAD PROJECT | D15: CA23007 | E15: KINOSIS K1B | F15: STEAM | G15: 29103-25J-151-01 | H15: 29103-3"-ST-1501-DASB0-64H | I15: 29103-FV-1052 | K15: FCV | M15: 1000383565 | N15: PDA200 | O15: 5CB TC | P15: TC c/w S17400 carrier | Q15: 1000389737 | R15: P25E HT | S15: Inch | T15: 3" | U15: F005340809 | V15: DVC-6200 | W15: V | X15: 900 | Y15: N/A | Z15: N/A | AA15: 1.5 | AB15: Flanged | AC15: N/A | AD15: N/A | AE15: 0C00070.2 | CE15: EMERSON | CF15: TREX | CG15: 210100082367 | CH15: '2026-07-31 | CJ15: Levy Ostrup
C16: K1B WELL PAD PROJECT | D16: CA23007 | E16: KINOSIS K1B | F16: STEAM | G16: 29103-25J-161-01 | H16: 29103-6"-ST-1602-DASB0-64H | I16: 29103-FV-1061 | K16: FCV | M16: 1000383604 | N16: PDA200 | O16: 5CB TC | P16: TC c/w S17400 carrier | Q16: 1000383597 | R16: P3E HT | S16: Inch | T16: 4" | U16: F005340803 | V16: DVC-6200 | W16: V | X16: 900 | Y16: N/A | Z16: N/A | AA16: 2.15 | AB16: Flanged | AC16: N/A | AD16: N/A | AE16: 0C00070.2 | CE16: EMERSON | CF16: TREX | CG16: 210100082367 | CH16: '2026-07-31 | CJ16: Levy Ostrup
C17: K1B WELL PAD PROJECT | D17: CA23007 | E17: KINOSIS K1B | F17: STEAM | G17: 29103-25J-161-01 | H17: 29103-3"-ST-1601-DASB0-64H | I17: 29103-FV-1062 | K17: FCV | M17: 1000383535 | N17: PDA200 | O17: 5CB TC | P17: TC c/w S17400 carrier | Q17: 1000389753 | R17: P25E HT | S17: Inch | T17: 3" | U17: F005209241 | V17: DVC-6200 | W17: V | X17: 900 | Y17: N/A | Z17: N/A | AA17: 1.5 | AB17: Flanged | AC17: N/A | AD17: N/A | AE17: 0C00070.2 | CE17: EMERSON | CF17: TREX | CG17: 210100082367 | CH17: '2026-07-31 | CJ17: Levy Ostrup
... C19: K1B WELL PAD PROJECT | D19: CA23007 | E19: KINOSIS K1B | F19: STEAM | G19: 29103-25J-171-01 | H19: 29103-3"-ST-1701-DASB0-64H | I19: 29103-FV-1072 | K19: FCV | M19: 1000383566 | N19: PDA200 | O19: 5CB TC | P19: TC c/w S17400 carrier | Q19: 1000389738 | R19: P25E HT | S19: Inch | T19: 3" | U19: F005340818 | V19: DVC-6200 | W19: V | X19: 900 | Y19: N/A | Z19: N/A | AA19: 1.5 | AB19: Flanged | AC19: N/A | AD19: N/A | AE19: 0C00070.2 | CE19: EMERSON | CF19: TREX | CG19: 210100082367 | CH19: '2026-07-31 | CJ19: Levy Ostrup
C20: K1B WELL PAD PROJECT | D20: CA23007 | E20: KINOSIS K1B | F20: NATURAL GAS | G20: 29103-25J-111-01 | H20: 29103-1"-FG-1105-DLHB0-38H-ET | I20: 29103-FV-1015 | K20: FCV | M20: S-26-018955 | N20: 88 Spring & Diaphragm | O20: 316 SS | P20: 316 SS | Q20: N/A | R20: N/A | S20: Inch | T20: 0.8 | U20: F005452608 | V20: SVI3 SMART | W20: IV | X20: 1500 | Y20: N/A | Z20: N/A | AA20: 1 | AB20: Flanged | AC20: N/A | AD20: N/A | AE20: 0C18929.52 | CE20: EMERSON | CF20: TREX | CG20: 210100082367 | CH20: '2026-07-31 | CJ20: Levy Ostrup
C21: K1B WELL PAD PROJECT | D21: CA23007 | E21: KINOSIS K1B | F21: NATURAL GAS | G21: 29103-25J-131-01 | H21: 29103-1"-FG-1305-DLHB0-38H-ET | I21: 29103-FV-1035 | K21: FCV | M21: N/A | N21: 88 Spring & Diaphragm | O21: 316 SS | P21: 316 SS | Q21: N/A | R21: N/A | S21: Inch | T21: 0.8 | U21: N/A | V21: SVI3 SMART | W21: IV | X21: 1500 | Y21: N/A | Z21: N/A | AA21: 1 | AB21: Flanged | AC21: N/A | AD21: N/A | AE21: 0C18929.52 | CE21: EMERSON | CF21: TREX | CG21: 210100082367 | CH21: '2026-07-31 | CJ21: Levy Ostrup
C22: K1B WELL PAD PROJECT | D22: CA23007 | E22: KINOSIS K1B | F22: NATURAL GAS | G22: 29103-25J-151-01 | H22: 29103-1"-FG-1505-DLHB0-38H-ET | I22: 29103-FV-1055 | K22: FCV | M22: N/A | N22: 88 Spring & Diaphragm | O22: 316 SS | P22: 316 SS | Q22: N/A | R22: N/A | S22: Inch | T22: 0.8 | U22: N/A | V22: SVI3 SMART | W22: IV | X22: 1500 | Y22: N/A | Z22: N/A | AA22: 1 | AB22: Flanged | AC22: N/A | AD22: N/A | AE22: 0C18929.52 | CE22: EMERSON | CF22: TREX | CG22: 210100082367 | CH22: '2026-07-31 | CJ22: Levy Ostrup
C23: K1B WELL PAD PROJECT | D23: CA23007 | E23: KINOSIS K1B | F23: NATURAL GAS | G23: 29103-25J-111-01 | H23: 29103-1"-FG-1103-DLHB0-38H-ET | I23: 29103-KV-1013 | K23: PCV | M23: N/A | N23: VPVL100SR4/5BD | O23: 316 SS | P23: Xtreme | Q23: 25224154 | R23: 1/2" 4B36HBXTB2 | U23: N/A | V23: N/A | W23: VI | X23: 800 | Y23: N/A | Z23: N/A | AA23: 1/2" | AB23: Threaded | AC23: A47713296 | AD23: JS2D8314H301-24VDC | AE23: 0C7803.52 | CE23: EMERSON | CF23: TREX | CG23: 210100082367 | CH23: '2026-07-31 | CJ23: Levy Ostrup
C24: K1B WELL PAD PROJECT | D24: CA23007 | E24: KINOSIS K1B | F24: NATURAL GAS | G24: 29103-25J-112-01 | H24: 29103-1"-FG-1101-DLHB0-38H-ET | I24: 29103-KV-1017 | K24: PCV | M24: N/A | N24: VPVL100SR4/5BD | O24: 316 SS | P24: Xtreme | Q24: 25224157 | R24: 1/2" 4B36HBXTB2 | U24: N/A | V24: N/A | W24: VI | X24: 800 | Y24: N/A | Z24: N/A | AA24: 1/2" | AB24: Threaded | AC24: A47713296 | AD24: JS2D8314H301-24VDC | AE24: 0C7803.52 | CE24: EMERSON | CF24: TREX | CG24: 210100082367 | CH24: '2026-07-31 | CJ24: Levy Ostrup
C25: K1B WELL PAD PROJECT | D25: CA23007 | E25: KINOSIS K1B | F25: NATURAL GAS | G25: 29103-25J-121-01 | H25: 29103-1"-FG-1203-DLHB0-38H-ET | I25: 29103-KV-1023 | K25: PCV | M25: N/A | N25: VPVL100SR4/5BD | O25: 316 SS | P25: Xtreme | Q25: 25224155 | R25: 1/2" 4B36HBXTB2 | U25: N/A | V25: N/A | W25: VI | X25: 800 | Y25: N/A | Z25: N/A | AA25: 1/2" | AB25: Threaded | AC25: A47713296 | AD25: JS2D8314H301-24VDC | AE25: 0C7803.52 | CE25: EMERSON | CF25: TREX | CG25: 210100082367 | CH25: '2026-07-31 | CJ25: Levy Ostrup
C26: K1B WELL PAD PROJECT | D26: CA23007 | E26: KINOSIS K1B | F26: NATURAL GAS | G26: 29103-25J-122-01 | H26: 29103-1"-FG-1201-DLHB0-38H-ET | I26: 29103-KV-1027 | K26: PCV | M26: N/A | N26: VPVL100SR4/5BD | O26: 316 SS | P26: Xtreme | Q26: 25224106 | R26: 1/2" 4B36HBXTB2 | U26: N/A | V26: N/A | W26: VI | X26: 800 | Y26: N/A | Z26: N/A | AA26: 1/2" | AB26: Threaded | AC26: A47713296 | AD26: JS2D8314H301-24VDC | AE26: 0C7803.52 | CE26: EMERSON | CF26: TREX | CG26: 210100082367 | CH26: '2026-07-31 | CJ26: Levy Ostrup
C27: K1B WELL PAD PROJECT | D27: CA23007 | E27: KINOSIS K1B | F27: NATURAL GAS | G27: 29103-25J-131-01 | H27: 29103-1"-FG-1303-DLHB0-38H-ET | I27: 29103-KV-1033 | K27: PCV | M27: N/A | N27: VPVL100SR4/5BD | O27: 316 SS | P27: Xtreme | Q27: 25224111 | R27: 1/2" 4B36HBXTB2 | U27: N/A | V27: N/A | W27: VI | X27: 800 | Y27: N/A | Z27: N/A | AA27: 1/2" | AB27: Threaded | AC27: A47713296 | AD27: JS2D8314H301-24VDC | AE27: 0C7803.52 | CE27: EMERSON | CF27: TREX | CG27: 210100082367 | CH27: '2026-07-31 | CJ27: Levy Ostrup
C28: K1B WELL PAD PROJECT | D28: CA23007 | E28: KINOSIS K1B | F28: NATURAL GAS | G28: 29103-25J-132-01 | H28: 29103-1"-FG-1301-DLHB0-38H-ET | I28: 29103-KV-1037 | K28: PCV | M28: N/A | N28: VPVL100SR4/5BD | O28: 316 SS | P28: Xtreme | Q28: 25224153 | R28: 1/2" 4B36HBXTB2 | U28: N/A | V28: N/A | W28: VI | X28: 800 | Y28: N/A | Z28: N/A | AA28: 1/2" | AB28: Threaded | AC28: A47713296 | AD28: JS2D8314H301-24VDC | AE28: 0C7803.52 | CE28: EMERSON | CF28: TREX | CG28: 210100082367 | CH28: '2026-07-31 | CJ28: Levy Ostrup
C29: K1B WELL PAD PROJECT | D29: CA23007 | E29: KINOSIS K1B | F29: NATURAL GAS | G29: 29103-25J-141-01 | H29: 29103-1"-FG-1403-DLHB0-38H-ET | I29: 29103-KV-1043 | K29: PCV | M29: N/A | N29: VPVL100SR4/5BD | O29: 316 SS | P29: Xtreme | Q29: 25224152 | R29: 1/2" 4B36HBXTB2 | U29: N/A | V29: N/A | W29: VI | X29: 800 | Y29: N/A | Z29: N/A | AA29: 1/2" | AB29: Threaded | AC29: A47713296 | AD29: JS2D8314H301-24VDC | AE29: 0C7803.52 | CE29: EMERSON | CF29: TREX | CG29: 210100082367 | CH29: '2026-07-31 | CJ29: Levy Ostrup
C30: K1B WELL PAD PROJECT | D30: CA23007 | E30: KINOSIS K1B | F30: NATURAL GAS | G30: 29103-25J-142-01 | H30: 29103-1"-FG-1401-DLHB0-38H-ET | I30: 29103-KV-1047 | K30: PCV | M30: N/A | N30: VPVL100SR4/5BD | O30: 316 SS | P30: Xtreme | Q30: 25224181 | R30: 1/2" 4B36HBXTB2 | U30: N/A | V30: N/A | W30: VI | X30: 800 | Y30: N/A | Z30: N/A | AA30: 1/2" | AB30: Threaded | AC30: A47713296 | AD30: JS2D8314H301-24VDC | AE30: 0C7803.52 | CE30: EMERSON | CF30: TREX | CG30: 210100082367 | CH30: '2026-07-31 | CJ30: Levy Ostrup
C31: K1B WELL PAD PROJECT | D31: CA23007 | E31: KINOSIS K1B | F31: NATURAL GAS | G31: 29103-25J-151-01 | H31: 29103-1"-FG-1503-DLHB0-38H-ET | I31: 29103-KV-1053 | K31: PCV | M31: N/A | N31: VPVL100SR4/5BD | O31: 316 SS | P31: Xtreme | Q31: 25224113 | R31: 1/2" 4B36HBXTB2 | U31: N/A | V31: N/A | W31: VI | X31: 800 | Y31: N/A | Z31: N/A | AA31: 1/2" | AB31: Threaded | AC31: A47713296 | AD31: JS2D8314H301-24VDC | AE31: 0C7803.52 | CE31: EMERSON | CF31: TREX | CG31: 210100082367 | CH31: '2026-07-31 | CJ31: Levy Ostrup
C32: K1B WELL PAD PROJECT | D32: CA23007 | E32: KINOSIS K1B | F32: NATURAL GAS | G32: 29103-25J-152-01 | H32: 29103-1"-FG-1501-DLHB0-38H-ET | I32: 29103-KV-1057 | K32: PCV | M32: N/A | N32: VPVL100SR4/5BD | O32: 316 SS | P32: Xtreme | Q32: 25224184 | R32: 1/2" 4B36HBXTB2 | U32: N/A | V32: N/A | W32: VI | X32: 800 | Y32: N/A | Z32: N/A | AA32: 1/2" | AB32: Threaded | AC32: A47713296 | AD32: JS2D8314H301-24VDC | AE32: 0C7803.52 | CE32: EMERSON | CF32: TREX | CG32: 210100082367 | CH32: '2026-07-31 | CJ32: Levy Ostrup
C33: K1B WELL PAD PROJECT | D33: CA23007 | E33: KINOSIS K1B | F33: NATURAL GAS | G33: 29103-25J-161-01 | H33: 29103-1"-FG-1603-DLHB0-38H-ET | I33: 29103-KV-1063 | K33: PCV | M33: N/A | N33: VPVL100SR4/5BD | O33: 316 SS | P33: Xtreme | Q33: 25224177 | R33: 1/2" 4B36HBXTB2 | U33: N/A | V33: N/A | W33: VI | X33: 800 | Y33: N/A | Z33: N/A | AA33: 1/2" | AB33: Threaded | AC33: A47713296 | AD33: JS2D8314H301-24VDC | AE33: 0C7803.52 | CE33: EMERSON | CF33: TREX | CG33: 210100082367 | CH33: '2026-07-31 | CJ33: Levy Ostrup
C34: K1B WELL PAD PROJECT | D34: CA23007 | E34: KINOSIS K1B | F34: NATURAL GAS | G34: 29103-25J-162-01 | H34: 29103-1"-FG-1601-DLHB0-38H-ET | I34: 29103-KV-1067 | K34: PCV | M34: N/A | N34: VPVL100SR4/5BD | O34: 316 SS | P34: Xtreme | Q34: 25224175 | R34: 1/2" 4B36HBXTB2 | U34: N/A | V34: N/A | W34: VI | X34: 800 | Y34: N/A | Z34: N/A | AA34: 1/2" | AB34: Threaded | AC34: A47713296 | AD34: JS2D8314H301-24VDC | AE34: 0C7803.52 | CE34: EMERSON | CF34: TREX | CG34: 210100082367 | CH34: '2026-07-31 | CJ34: Levy Ostrup
... C36: K1B WELL PAD PROJECT | D36: CA23007 | E36: KINOSIS K1B | F36: NATURAL GAS | G36: 29103-25J-172-01 | H36: 29103-1"-FG-1701-DLHB0-38H-ET | I36: 29103-KV-1077 | K36: PCV | M36: N/A | N36: VPVL100SR4/5BD | O36: 316 SS | P36: Xtreme | Q36: 25224148 | R36: 1/2" 4B36HBXTB2 | U36: N/A | V36: N/A | W36: VI | X36: 800 | Y36: N/A | Z36: N/A | AA36: 1/2" | AB36: Threaded | AC36: A47713296 | AD36: JS2D8314H301-24VDC | AE36: 0C7803.52 | CE36: EMERSON | CF36: TREX | CG36: 210100082367 | CH36: '2026-07-31 | CJ36: Levy Ostrup
C37: K1B WELL PAD PROJECT | D37: CA23007 | E37: KINOSIS K1B | F37: PRODUCED EMULSION | G37: 29103-25J-112-01 | H37: 29103-4"-PE-1101-DAPC0-64H-ET | I37: 29103-PV-1014 | K37: PCV | M37: 1000383571 | N37: 667-46 Spring & Diaphragm | O37: 5CB TC | P37: TC c/w S17400 carrier | Q37: 1000389743 | R37: P25E | S37: Inch | T37: 1.5 | U37: F005209232 | V37: DVC6200-PD SMART | W37: V | X37: 900 | Y37: N/A | Z37: N/A | AA37: 3 | AB37: Flanged | AC37: N/A | AD37: N/A | AE37: 0C00070.2 | CE37: EMERSON | CF37: TREX | CG37: 210100082367 | CH37: '2026-07-31 | CJ37: Levy Ostrup
C38: K1B WELL PAD PROJECT | D38: CA23007 | E38: KINOSIS K1B | F38: PRODUCED EMULSION | G38: 29103-25J-122-01 | H38: 29103-4"-PE-1201-DAPC0-64H-ET | I38: 29103-PV-1024 | K38: PCV | M38: 1000383540 | N38: 667-46 Spring & Diaphragm | O38: 5CB TC | P38: TC c/w S17400 carrier | Q38: N/A | R38: P25E | S38: Inch | T38: 1.5 | U38: F005209243 | V38: DVC6200-PD SMART | W38: V | X38: 900 | Y38: N/A | Z38: N/A | AA38: 3 | AB38: Flanged | AC38: N/A | AD38: N/A | AE38: 0C00070.2 | CE38: EMERSON | CF38: TREX | CG38: 210100082367 | CH38: '2026-07-31 | CJ38: Levy Ostrup
C39: K1B WELL PAD PROJECT | D39: CA23007 | E39: KINOSIS K1B | F39: PRODUCED EMULSION | G39: 29103-25J-132-01 | H39: 29103-4"-PE-1301-DAPC0-64H-ET | I39: 29103-PV-1034 | K39: PCV | M39: 1000383572 | N39: 667-46 Spring & Diaphragm | O39: 5CB TC | P39: TC c/w S17400 carrier | Q39: N/A | R39: P25E | S39: Inch | T39: 1.5 | U39: F005340817 | V39: DVC6200-PD SMART | W39: V | X39: 900 | Y39: N/A | Z39: N/A | AA39: 3 | AB39: Flanged | AC39: N/A | AD39: N/A | AE39: 0C00070.2 | CE39: EMERSON | CF39: TREX | CG39: 210100082367 | CH39: '2026-07-31 | CJ39: Levy Ostrup
C40: K1B WELL PAD PROJECT | D40: CA23007 | E40: KINOSIS K1B | F40: PRODUCED EMULSION | G40: 29103-25J-142-01 | H40: 29103-4"-PE-1401-DAPC0-64H-ET | I40: 29103-PV-1044 | K40: PCV | M40: 1000383541 | N40: 667-46 Spring & Diaphragm | O40: 5CB TC | P40: TC c/w S17400 carrier | Q40: N/A | R40: P25E | S40: Inch | T40: 1.5 | U40: F005209347 | V40: DVC6200-PD SMART | W40: V | X40: 900 | Y40: N/A | Z40: N/A | AA40: 3 | AB40: Flanged | AC40: N/A | AD40: N/A | AE40: 0C00070.2 | CE40: EMERSON | CF40: TREX | CG40: 210100082367 | CH40: '2026-07-31 | CJ40: Levy Ostrup
C41: K1B WELL PAD PROJECT | D41: CA23007 | E41: KINOSIS K1B | F41: PRODUCED EMULSION | G41: 29103-25J-152-01 | H41: 29103-4"-PE-1501-DAPC0-64H-ET | I41: 29103-PV-1054 | K41: PCV | M41: 1000383573 | N41: 667-46 Spring & Diaphragm | O41: 5CB TC | P41: TC c/w S17400 carrier | Q41: N/A | R41: P25E | S41: Inch | T41: 1.5 | U41: F005340832 | V41: DVC6200-PD SMART | W41: V | X41: 900 | Y41: N/A | Z41: N/A | AA41: 3 | AB41: Flanged | AC41: N/A | AD41: N/A | AE41: 0C00070.2 | CE41: EMERSON | CF41: TREX | CG41: 210100082367 | CH41: '2026-07-31 | CJ41: Levy Ostrup
C42: K1B WELL PAD PROJECT | D42: CA23007 | E42: KINOSIS K1B | F42: PRODUCED EMULSION | G42: 29103-25J-162-01 | H42: 29103-4"-PE-1601-DAPC0-64H-ET | I42: 29103-PV-1064 | K42: PCV | M42: 1000383542 | N42: 667-46 Spring & Diaphragm | O42: 5CB TC | P42: TC c/w S17400 carrier | Q42: N/A | R42: P25E | S42: Inch | T42: 1.5 | U42: F005209242 | V42: DVC6200-PD SMART | W42: V | X42: 900 | Y42: N/A | Z42: N/A | AA42: 3 | AB42: Flanged | AC42: N/A | AD42: N/A | AE42: 0C00070.2 | CE42: EMERSON | CF42: TREX | CG42: 210100082367 | CH42: '2026-07-31 | CJ42: Levy Ostrup
...

Sheet Transmitter Log 100
A1: =HYPERLINK("#Dashboard!A1","<< Dashboard")
A2: Control | B2: Header Info | C2: PART 1 – Project Description | F2: PART 2 – Transmitter Description | V2: PART 3 – Visual Inspection | AH2: PART 4 – Procedure | AV2: PART 5 – Test Equipment | BH2: PART 6 – Test Results | CW2: PART 7 – Remarks | CX2: PART 8 – Inspected/Approved By
A3: Export to PDF (Y/N) | B3: Customer Ref# | C3: Project | D3: Location | E3: Contract # | F3: Tag | G3: Transmitter Type | H3: System Number | I3: Service | J3: P&ID Number | K3: Line Number | L3: Make | M3: Model | N3: Serial Number | O3: Calibration Range | P3: Instrument Range | Q3: Repeatability | R3: Local Display | S3: Signal Type | T3: K-Factor | U3: Scale Factor | V3: 1. Stamped SS instrument tag attached. (Initial/NA) | W3: 2. Stamped SS cable tag attached. (Initial/NA) | X3: 3. Device installed as per P&ID drawings and installation details. (Initial/NA) | Y3: 4. Equipment accessible and easy to maintain. (Initial/NA) | Z3: 5. Verify impulse line(s) are correctly installed. (Initial/NA) | AA3: 6. Manifold/isolation valve(s) conform to data sheets. (Initial/NA) | AB3: 7. Wiring polarity correct and properly labeled. (Initial/NA) | AC3: 8. Tug test terminations. (Initial/NA) | AD3: 9. Perform insulation check on wiring. (Initial/NA) | AE3: 10. Check enclosure labeling. (Initial/NA) | AF3: 11. Check enclosure mounting/orientation. (Initial/NA) | AG3: 12. Check boot and seal(s). (All openings sealed) (Initial/NA) | AH3: 1. Power the transmitter and measure the voltage (VDC) | AI3: 2. Perform leak check procedure. | AJ3: 3. Power enclosure heater and verify operations. | AK3: 4. Power traced tubing bundle(s) and verify operation. | AL3: 5. Disconnect wire (open loop) and verify fault. | AM3: 6. Verify local display(s) operational. | AN3: 7. Ensure process sensing/impulse lines are open. | AO3: 8. Verify signal configuration. | AP3: 9. Ensure manifolds are placed back into service position. | AQ3: 10. Confirm controller action as per loop narrative. | AR3: 11. Graphic display matches with function. | AS3: 12. Construction QA/QC Documents Verified. | AT3: 13. Is loop left energized and ready for service. | AU3: 14. Place "pre-commissioned" tag on instrument. | AV3: Test Equip 1 - Make | AW3: Test Equip 1 - Model | AX3: Test Equip 1 - Serial | AY3: Test Equip 1 - Calibration Date | AZ3: Test Equip 2 - Make | BA3: Test Equip 2 - Model | BB3: Test Equip 2 - Serial | BC3: Test Equip 2 - Calibration Date | BD3: Test Equip 3 - Make | BE3: Test Equip 3 - Model | BF3: Test Equip 3 - Serial | BG3: Test Equip 3 - Calibration Date | BH3: 0% Input Upscale | BI3: 0% Input Downscale | BJ3: 0% Output Upscale | BK3: 0% Output Downscale | BL3: 0% Local Display Upscale | BM3: 0% Local Display Downscale | BN3: 0% DCS Display/Units Upscale | BO3: 0% DCS Display/Units Downscale | BP3: 25% Input Upscale | BQ3: 25% Input Downscale | BR3: 25% Output Upscale | BS3: 25% Output Downscale | BT3: 25% Local Display Upscale | BU3: 25% Local Display Downscale | BV3: 25% DCS Display/Units Upscale | BW3: 25% DCS Display/Units Downscale | BX3: 50% Input Upscale | BY3: 50% Input Downscale | BZ3: 50% Output Upscale | CA3: 50% Output Downscale | CB3: 50% Local Display Upscale | CC3: 50% Local Display Downscale | CD3: 50% DCS Display/Units Upscale | CE3: 50% DCS Display/Units Downscale | CF3: 75% Input Upscale | CG3: 75% Input Downscale | CH3: 75% Output Upscale | CI3: 75% Output Downscale | CJ3: 75% Local Display Upscale | CK3: 75% Local Display Downscale | CL3: 75% DCS Display/Units Upscale | CM3: 75% DCS Display/Units Downscale | CN3: 100% Input Upscale | CO3: 100% Input Downscale | CP3: 100% Output Upscale | CQ3: 100% Output Downscale | CR3: 100% Local Display Upscale | CS3: 100% Local Display Downscale | CT3: 100% DCS Display/Units Upscale | CU3: 100% DCS Display/Units Downscale | CV3: System Results | CW3: Remarks | CX3: Yanda QA Representative - Name | CY3: Yanda QA Representative - Date | CZ3: Yanda QA Representative - Signature | DA3: Client Representative - Name | DB3: Client Representative - Date | DC3: Client Representative - Signature
A4: N | C4: K1B WELL PAD PROJECT | D4: KINOSIS K1B | E4: CA23007 | F4: 29103-PIT-1014 | G4: Pressure Transmitter | H4: PRODUCED EMULSION | I4: PAD A P01 PRODUCED EMULSION PRES | J4: 29103-25J-112-01 | K4: 29103-4"-PE-1101-DAPC0-64H-ET | L4: ROSEMOUNT | M4: 3051T | N4: 26SIPG3884781 | O4: 0 - 6000 kPa-g | P4: -101 - 27580 kPa-g | Q4: N/A | R4: Yes | S4: 4-20 mA w/ HART | T4: N/A | U4: N/A | V4: LO | W4: LO | X4: LO | Y4: LO | Z4: N/A | AA4: LO | AB4: LO | AC4: LO | AD4: N/A | AE4: LO | AF4: LO | AG4: LO | AH4: 24.1 | AI4: Pass | AJ4: Pass | AK4: Pass | AL4: Pass | AM4: Pass | AN4: Pass | AO4: Pass | AP4: Pass | AQ4: Pass | AR4: Pass | AS4: Pass | AT4: Pass | AU4: Pass | CV4: Pass | CW4: Example row - for reference only. Delete or overwrite before logging real data. | CX4: L. Olsen | CY4: '2026-08-01
C5: K1B WELL PAD PROJECT | D5: KINOSIS K1B | E5: CA23007 | F5: 29103-FIT-1011 | G5: Vortex Flow Meter | H5: STEAM | I5: PAD A S01 HP STM TO INJC WELL TOE FLOW CTRL | J5: 29103-25J-112-01 | K5: 29103-4"-ST-1100-DASSBO-64H | L5: ROSEMOUNT | M5: 8800DF010SA8N1D1K6M5Q5Q8Q66Q71Q77 | N5: 13949848 | O5: 0-15,000 kg/h | P5: 765-38273 kg/h | Q5: N/A | R5: Yes | S5: 4-20 mA w/ HART | T5: 10.754 | U5: N/A | V5: LO | W5: LO | X5: LO | Y5: LO | Z5: N/A | AA5: N/A | AB5: LO | AC5: LO | AD5: N/A | AE5: LO | AF5: LO | AG5: LO | AH5: 23.8 | AI5: Pass | AJ5: N/A | AK5: N/A | AL5: Pass | AM5: Pass | AN5: N/A | AO5: Pass | AP5: N/A | AQ5: N/A | AR5: Pass | AS5: Pass | AT5: N/A | AU5: N/A | AV5: EMERSON | AW5: TREX | AX5: 210100082367 | AY5: '2026-07-31 | CX5: Levy Ostrup | CY5: '2026-08-01
C6: K1B WELL PAD PROJECT | D6: KINOSIS K1B | E6: CA23007 | F6: 29103-FIT-1012 | G6: Vortex Flow Meter | H6: STEAM | I6: PAD A S01 HP STM TO INJC WELL HEEL FLOW CTRL | J6: 29103-25J-111-01 | K6: 29103-3"-ST-1101-DASBO-64H | L6: ROSEMOUNT | M6: 8800DF010SA8N1D1K6M5Q5Q8Q66Q71Q77 | N6: 13948492 | O6: 0-15,000 kg/h | P6: 765-38273 kg/h | Q6: N/A | R6: Yes | S6: 4-20 mA w/ HART | T6: 10.614 | U6: N/A | V6: LO | W6: LO | X6: LO | Y6: LO | Z6: N/A | AA6: N/A | AB6: LO | AC6: LO | AD6: N/A | AE6: LO | AF6: LO | AG6: LO | AH6: 23.8 | AI6: Pass | AJ6: N/A | AK6: N/A | AL6: Pass | AM6: Pass | AN6: N/A | AO6: Pass | AP6: N/A | AQ6: N/A | AR6: Pass | AS6: Pass | AT6: N/A | AU6: N/A | AV6: EMERSON | AW6: TREX | AX6: 210100082367 | AY6: '2026-07-31 | CX6: Levy Ostrup | CY6: '2026-08-01
C7: K1B WELL PAD PROJECT | D7: KINOSIS K1B | E7: CA23007 | F7: 29103-FIT-1021 | G7: Vortex Flow Meter | H7: STEAM | I7: PAD A S02 HP STM TO INJC WELL TOE FLOW CTRL | J7: 29103-25J-121-01 | K7: 29103-4"-ST-1200-DASSBO-64H | L7: ROSEMOUNT | M7: 8800DF010SA8N1D1K6M5Q5Q8Q66Q71Q77 | N7: 13939849 | O7: 0-15,000 kg/h | P7: 765-38273 kg/h | Q7: N/A | R7: Yes | S7: 4-20 mA w/ HART | T7: 10.646 | U7: N/A | V7: LO | W7: LO | X7: LO | Y7: LO | Z7: N/A | AA7: N/A | AB7: LO | AC7: LO | AD7: N/A | AE7: LO | AF7: LO | AG7: LO | AH7: 23.5 | AI7: Pass | AJ7: N/A | AK7: N/A | AL7: Pass | AM7: Pass | AN7: N/A | AO7: Pass | AP7: N/A | AQ7: N/A | AR7: Pass | AS7: Pass | AT7: N/A | AU7: N/A | AV7: EMERSON | AW7: TREX | AX7: 210100082367 | AY7: '2026-07-31 | CX7: Levy Ostrup | CY7: '2026-08-22
C8: K1B WELL PAD PROJECT | D8: KINOSIS K1B | E8: CA23007 | F8: 29103-FIT-1022 | G8: Vortex Flow Meter | H8: STEAM | I8: PAD A S02 HP STM TO INJC WELL HEEL FLOW CTRL | J8: 29103-25J-121-01 | K8: 29103-3"-ST-1201-DASBO-64H | L8: ROSEMOUNT | M8: 8800DF010SA8N1D1K6M5Q5Q8Q66Q71Q77 | N8: 13949011 | O8: 0-15,000 kg/h | P8: 765-38273 kg/h | Q8: N/A | R8: Yes | S8: 4-20 mA w/ HART | T8: 10.491 | U8: N/A | V8: LO | W8: LO | X8: LO | Y8: LO | Z8: N/A | AA8: N/A | AB8: LO | AC8: LO | AD8: N/A | AE8: LO | AF8: LO | AG8: LO | AH8: 23.8 | AI8: Pass | AJ8: N/A | AK8: N/A | AL8: Pass | AM8: Pass | AN8: N/A | AO8: Pass | AP8: N/A | AQ8: N/A | AR8: Pass | AS8: N/A | AT8: N/A | AU8: N/A | AV8: EMERSON | AW8: TREX | AX8: 210100082367 | AY8: '2026-07-31 | CX8: Levy Ostrup | CY8: '2026-08-01
C9: K1B WELL PAD PROJECT | D9: KINOSIS K1B | E9: CA23007 | F9: 29103-FIT-1031 | G9: Vortex Flow Meter | H9: STEAM | I9: PAD A S03 HP STM TO INJC WELL TOE FLOW CTRL | J9: 29103-25J-131-01 | K9: 29103-4"-ST-1300-DASSBO-64H | L9: ROSEMOUNT | M9: 8800DF010SA8N1D1K6M5Q5Q8Q66Q71Q77 | N9: 13949012 | O9: 0-15,000 kg/h | P9: 765-38273 kg/h | Q9: N/A | R9: Yes | S9: 4-20 mA w/ HART | T9: 10.67 | U9: N/A | V9: LO | W9: LO | X9: LO | Y9: LO | Z9: N/A | AA9: N/A | AB9: LO | AC9: LO | AD9: N/A | AE9: LO | AF9: LO | AG9: LO | AH9: 23.5 | AI9: Pass | AJ9: N/A | AK9: N/A | AL9: Pass | AM9: Pass | AN9: N/A | AO9: Pass | AP9: N/A | AQ9: N/A | AR9: Pass | AS9: Pass | AT9: N/A | AU9: N/A | AV9: EMERSON | AW9: TREX | AX9: 210100082367 | AY9: '2026-07-31 | CX9: Levy Ostrup | CY9: '2026-08-01
C10: K1B WELL PAD PROJECT | D10: KINOSIS K1B | E10: CA23007 | F10: 29103-FIT-1032 | G10: Vortex Flow Meter | H10: STEAM | I10: PAD A S03 HP STM TO INJC WELL HEEL FLOW CTRL | J10: 29103-25J-131-01 | K10: 29103-3"-ST-1301-DASBO-64H | L10: ROSEMOUNT | M10: 8800DF010SA8N1D1K6M5Q5Q8Q66Q71Q77 | N10: 13950338 | O10: 0-15,000 kg/h | P10: 765-38273 kg/h | Q10: N/A | R10: Yes | S10: 4-20 mA w/ HART | T10: 10.429 | U10: N/A | V10: LO | W10: LO | X10: LO | Y10: LO | Z10: N/A | AA10: N/A | AB10: LO | AC10: LO | AD10: N/A | AE10: LO | AF10: LO | AG10: LO | AH10: 23.8 | AI10: Pass | AJ10: N/A | AK10: N/A | AL10: Pass | AM10: Pass | AN10: N/A | AO10: Pass | AP10: N/A | AQ10: N/A | AR10: Pass | AS10: Pass | AT10: N/A | AU10: N/A | AV10: EMERSON | AW10: TREX | AX10: 210100082367 | AY10: '2026-07-31 | CX10: Levy Ostrup | CY10: '2026-08-01
C11: K1B WELL PAD PROJECT | D11: KINOSIS K1B | E11: CA23007 | F11: 29103-FIT-1041 | G11: Vortex Flow Meter | H11: STEAM | I11: PAD A S04 HP STM TO INJC WELL TOE FLOW CTRL | J11: 29103-25J-141-01 | K11: 29103-4"-ST-1400-DASSBO-64H | L11: ROSEMOUNT | M11: 8800DF010SA8N1D1K6M5Q5Q8Q66Q71Q77 | N11: 13950856 | O11: 0-15,000 kg/h | P11: 765-38273 kg/h | Q11: N/A | R11: Yes | S11: 4-20 mA w/ HART | T11: 10.681 | U11: N/A | V11: LO | W11: LO | X11: LO | Y11: LO | Z11: N/A | AA11: N/A | AB11: LO | AC11: LO | AD11: N/A | AE11: LO | AF11: LO | AG11: LO | AH11: 23.4 | AI11: Pass | AJ11: N/A | AK11: N/A | AL11: Pass | AM11: Pass | AN11: N/A | AO11: Pass | AP11: N/A | AQ11: N/A | AR11: Pass | AS11: Pass | AT11: N/A | AU11: N/A | AV11: EMERSON | AW11: TREX | AX11: 210100082367 | AY11: '2026-07-31 | CX11: Levy Ostrup | CY11: '2026-08-01
C12: K1B WELL PAD PROJECT | D12: KINOSIS K1B | E12: CA23007 | F12: 29103-FIT-1042 | G12: Vortex Flow Meter | H12: STEAM | I12: PAD A S04 HP STM TO INJC WELL HEEL FLOW CTRL | J12: 29103-25J-141-01 | K12: 29103-3"-ST-1401-DASBO-64H | L12: ROSEMOUNT | M12: 8800DF010SA8N1D1K6M5Q5Q8Q66Q71Q77 | N12: 13950339 | O12: 0-15,000 kg/h | P12: 765-38273 kg/h | Q12: N/A | R12: Yes | S12: 4-20 mA w/ HART | T12: 10.484 | U12: N/A | V12: LO | W12: LO | X12: LO | Y12: LO | Z12: N/A | AA12: N/A | AB12: LO | AC12: LO | AD12: N/A | AE12: LO | AF12: LO | AG12: LO | AH12: 23.3 | AI12: Pass | AJ12: N/A | AK12: N/A | AL12: Pass | AM12: Pass | AN12: N/A | AO12: Pass | AP12: N/A | AQ12: N/A | AR12: Pass | AS12: Pass | AT12: N/A | AU12: N/A | AV12: EMERSON | AW12: TREX | AX12: 210100082367 | AY12: '2026-07-31 | CX12: Levy Ostrup | CY12: '2026-08-01
C13: K1B WELL PAD PROJECT | D13: KINOSIS K1B | E13: CA23007 | F13: 29103-FIT-1051 | G13: Vortex Flow Meter | H13: STEAM | I13: PAD A S05 HP STM TO INJC WELL TOE FLOW CTRL | J13: 29103-25J-151-01 | K13: 29103-4"-ST-1500-DASSBO-64H | L13: ROSEMOUNT | M13: 8800DF010SA8N1D1K6M5Q5Q8Q66Q71Q77 | N13: 13950845 | O13: 0-15,000 kg/h | P13: 765-38273 kg/h | Q13: N/A | R13: Yes | S13: 4-20 mA w/ HART | T13: 10.76 | U13: N/A | V13: LO | W13: LO | X13: LO | Y13: LO | Z13: N/A | AA13: N/A | AB13: LO | AC13: LO | AD13: N/A | AE13: LO | AF13: LO | AG13: LO | AH13: 23.8 | AI13: Pass | AJ13: N/A | AK13: N/A | AL13: Pass | AM13: Pass | AN13: N/A | AO13: Pass | AP13: N/A | AQ13: N/A | AR13: Pass | AS13: Pass | AT13: N/A | AU13: N/A | AV13: EMERSON | AW13: TREX | AX13: 210100082367 | AY13: '2026-07-31 | CX13: Levy Ostrup | CY13: '2026-08-01
C14: K1B WELL PAD PROJECT | D14: KINOSIS K1B | E14: CA23007 | F14: 29103-FIT-1052 | G14: Vortex Flow Meter | H14: STEAM | I14: PAD A S05 HP STM TO INJC WELL HEEL FLOW CTRL | J14: 29103-25J-151-01 | K14: 29103-3"-ST-1501-DASBO-64H | L14: ROSEMOUNT | M14: 8800DF010SA8N1D1K6M5Q5Q8Q66Q71Q77 | N14: 13951880 | O14: 0-15,000 kg/h | P14: 765-38273 kg/h | Q14: N/A | R14: Yes | S14: 4-20 mA w/ HART | T14: 10.388 | U14: N/A | V14: LO | W14: LO | X14: LO | Y14: LO | Z14: N/A | AA14: N/A | AB14: LO | AC14: LO | AD14: N/A | AE14: LO | AF14: LO | AG14: LO | AH14: 23.8 | AI14: Pass | AJ14: N/A | AK14: N/A | AL14: Pass | AM14: Pass | AN14: N/A | AO14: Pass | AP14: N/A | AQ14: N/A | AR14: Pass | AS14: Pass | AT14: N/A | AU14: N/A | AV14: EMERSON | AW14: TREX | AX14: 210100082367 | AY14: '2026-07-31 | CX14: Levy Ostrup | CY14: '2026-08-01
C15: K1B WELL PAD PROJECT | D15: KINOSIS K1B | E15: CA23007 | F15: 29103-FIT-1061 | G15: Vortex Flow Meter | H15: STEAM | I15: PAD A S06 HP STM TO INJC WELL TOE FLOW CTRL | J15: 29103-25J-161-01 | K15: 29103-4"-ST-1600-DASSBO-64H | L15: ROSEMOUNT | M15: 8800DF010SA8N1D1K6M5Q5Q8Q66Q71Q77 | N15: 13951881 | O15: 0-15,000 kg/h | P15: 765-38273 kg/h | Q15: N/A | R15: Yes | S15: 4-20 mA w/ HART | T15: 10.694 | U15: N/A | V15: LO | W15: LO | X15: LO | Y15: LO | Z15: N/A | AA15: N/A | AB15: LO | AC15: LO | AD15: N/A | AE15: LO | AF15: LO | AG15: LO | AH15: 23.8 | AI15: Pass | AJ15: N/A | AK15: N/A | AL15: Pass | AM15: Pass | AN15: N/A | AO15: Pass | AP15: N/A | AQ15: N/A | AR15: Pass | AS15: Pass | AT15: N/A | AU15: N/A | AV15: EMERSON | AW15: TREX | AX15: 210100082367 | AY15: '2026-07-31 | CX15: Levy Ostrup | CY15: '2026-08-01
C16: K1B WELL PAD PROJECT | D16: KINOSIS K1B | E16: CA23007 | F16: 29103-FIT-1062 | G16: Vortex Flow Meter | H16: STEAM | I16: PAD A S06 HP STM TO INJC WELL HEEL FLOW CTRL | J16: 29103-25J-161-01 | K16: 29103-3"-ST-1601-DASBO-64H | L16: ROSEMOUNT | M16: 8800DF010SA8N1D1K6M5Q5Q8Q66Q71Q77 | N16: 13950340 | O16: 0-15,000 kg/h | P16: 765-38273 kg/h | Q16: N/A | R16: Yes | S16: 4-20 mA w/ HART | T16: 10.661 | U16: N/A | V16: LO | W16: LO | X16: LO | Y16: LO | Z16: N/A | AA16: N/A | AB16: LO | AC16: LO | AD16: N/A | AE16: LO | AF16: LO | AG16: LO | AH16: 23.5 | AI16: Pass | AJ16: N/A | AK16: N/A | AL16: Pass | AM16: Pass | AN16: N/A | AO16: Pass | AP16: N/A | AQ16: N/A | AR16: Pass | AS16: Pass | AT16: N/A | AU16: N/A | AV16: EMERSON | AW16: TREX | AX16: 210100082367 | AY16: '2026-07-31 | CX16: Levy Ostrup | CY16: '2026-08-01
C17: K1B WELL PAD PROJECT | D17: KINOSIS K1B | E17: CA23007 | F17: 29103-FIT-1071 | G17: Vortex Flow Meter | H17: STEAM | I17: PAD A S07 HP STM TO INJC WELL TOE FLOW CTRL | J17: 29103-25J-171-01 | K17: 29103-4"-ST-1700-DASSBO-64H | L17: ROSEMOUNT | M17: 8800DF010SA8N1D1K6M5Q5Q8Q66Q71Q77 | N17: 13950858 | O17: 0-15,000 kg/h | P17: 765-38273 kg/h | Q17: N/A | R17: Yes | S17: 4-20 mA w/ HART | T17: N/A | U17: N/A | V17: LO | W17: LO | X17: LO | Y17: LO | Z17: N/A | AA17: N/A | AB17: LO | AC17: LO | AD17: N/A | AE17: LO | AF17: LO | AG17: LO | AH17: 23.5 | AI17: Pass | AJ17: N/A | AK17: N/A | AL17: Pass | AM17: Pass | AN17: N/A | AO17: Pass | AP17: N/A | AQ17: N/A | AR17: Pass | AS17: Pass | AT17: N/A | AU17: N/A | AV17: EMERSON | AW17: TREX | AX17: 210100082367 | AY17: '2026-07-31 | CX17: Levy Ostrup | CY17: '2026-08-01
C18: K1B WELL PAD PROJECT | D18: KINOSIS K1B | E18: CA23007 | F18: 29103-FIT-1072 | G18: Vortex Flow Meter | H18: STEAM | I18: PAD A S07 HP STM TO INJC WELL HEEL FLOW CTRL | J18: 29103-25J-171-01 | K18: 29103-3"-ST-1701-DASBO-64H | L18: ROSEMOUNT | M18: 8800DF010SA8N1D1K6M5Q5Q8Q66Q71Q77 | N18: 13951882 | O18: 0-15,000 kg/h | P18: 765-38273 kg/h | Q18: N/A | R18: Yes | S18: 4-20 mA w/ HART | T18: 10.743 | U18: N/A | V18: LO | W18: LO | X18: LO | Y18: LO | Z18: N/A | AA18: N/A | AB18: LO | AC18: LO | AD18: N/A | AE18: LO | AF18: LO | AG18: LO | AH18: 23.8 | AI18: Pass | AJ18: N/A | AK18: N/A | AL18: Pass | AM18: Pass | AN18: N/A | AO18: Pass | AP18: N/A | AQ18: N/A | AR18: Pass | AS18: Pass | AT18: N/A | AU18: N/A | AV18: EMERSON | AW18: TREX | AX18: 210100082367 | AY18: '2026-07-31 | CX18: Levy Ostrup | CY18: '2026-08-01
C19: K1B WELL PAD PROJECT | D19: KINOSIS K1B | E19: CA23007 | F19: 29103-PIT-1200 | G19: Pressure Transmitter | H19: STEAM | I19: PAD A HP STEAM TO WELL PAD | J19: 29103-25J-106-01 | K19: 29103-16"-ST-1802-DASB0-90H | L19: ROSEMOUNT | M19: 3051T | N19: 26SIPG3884732 | O19: 0 - 10000 kPa-g | P19: -101 - 27580 kPa-g | Q19: N/A | R19: YES | S19: 4-20 mA w/ HART | T19: N/A | U19: N/A | V19: LO | W19: LO | X19: LO | Y19: LO | Z19: N/A | AA19: LO | AB19: LO | AC19: LO | AD19: N/A | AE19: LO | AF19: LO | AG19: LO | AH19: 23.4 | AI19: Pass | AJ19: N/A | AK19: N/A | AL19: Pass | AM19: Pass | AN19: N/A | AO19: Pass | AP19: N/A | AQ19: N/A | AR19: Pass | AS19: Pass | AT19: N/A | AU19: N/A | AV19: CRYSTAL ENGINEERING | AW19: IS33-36/5000 PSI | AX19: 4530-525617 | AY19: '2026-07-02 | AZ19: EMERSON | BA19: TREX | BB19: 210100082367 | BC19: '2026-07-31 | CX19: Levy Ostrup | CY19: '2026-08-01
C20: K1B WELL PAD PROJECT | D20: KINOSIS K1B | E20: CA23007 | F20: 29103-PIT-1201 | G20: Pressure Transmitter | H20: STEAM | I20: PAD A HP STEAM TO WELL PAD | J20: 29103-25J-106-01 | K20: 29103-16"-ST-1802-DASB0-90H | L20: ROSEMOUNT | M20: 3051T | N20: 26SIPG3884728 | O20: 0 - 10000 kPa-g | P20: -101 - 27580 kPa-g | Q20: N/A | R20: YES | S20: 4-20 mA w/ HART | T20: N/A | U20: N/A | V20: LO | W20: LO | X20: LO | Y20: LO | Z20: N/A | AA20: LO | AB20: LO | AC20: LO | AD20: N/A | AE20: LO | AF20: LO | AG20: LO | AH20: 23.4 | AI20: Pass | AJ20: N/A | AK20: N/A | AL20: Pass | AM20: Pass | AN20: N/A | AO20: Pass | AP20: N/A | AQ20: N/A | AR20: Pass | AS20: Pass | AT20: N/A | AU20: N/A | AV20: CRYSTAL ENGINEERING | AW20: IS33-36/5000 PSI | AX20: 4530-525617 | AY20: '2026-07-02 | AZ20: EMERSON | BA20: TREX | BB20: 210100082367 | BC20: '2026-07-31 | CX20: Levy Ostrup | CY20: '2026-08-01
C21: K1B WELL PAD PROJECT | D21: KINOSIS K1B | E21: CA23007 | F21: 29103-PIT-1202 | G21: Pressure Transmitter | H21: STEAM | I21: PAD A HP STEAM FROM FLOWLINE | J21: 29103-25J-106-01 | K21: 29103-16"-ST-1802-DASB0-90H | L21: ROSEMOUNT | M21: 3051T | N21: 26SIPG3884727 | O21: 0 - 10000 kPa-g | P21: -101 - 27580 kPa-g | Q21: N/A | R21: YES | S21: 4-20 mA w/ HART | T21: N/A | U21: N/A | V21: LO | W21: LO | X21: LO | Y21: LO | Z21: N/A | AA21: LO | AB21: LO | AC21: LO | AD21: N/A | AE21: LO | AF21: LO | AG21: LO | AH21: 23.4 | AI21: Pass | AJ21: N/A | AK21: N/A | AL21: Pass | AM21: Pass | AN21: N/A | AO21: Pass | AP21: N/A | AQ21: N/A | AR21: Pass | AS21: Pass | AT21: N/A | AU21: N/A | AV21: CRYSTAL ENGINEERING | AW21: IS33-36/5000 PSI | AX21: 4530-525617 | AY21: '2026-07-02 | AZ21: EMERSON | BA21: TREX | BB21: 210100082367 | BC21: '2026-07-31 | CX21: Levy Ostrup | CY21: '2026-08-01
C22: K1B WELL PAD PROJECT | D22: KINOSIS K1B | E22: CA23007 | F22: 29103-TIT-1100 | G22: Pressure Transmitter | H22: STEAM | I22: PAD A HP STEAM FROM FLOWLINE | J22: 29103-25J-106-01 | K22: 29103-16"-ST-1800-DASB0-90H | L22: ROSEMOUNT | M22: 3144P | N22: 26SITC3660170 | O22: -50 - 400ºC | P22: -200 - 600ºC | Q22: N/A | R22: YES | S22: 4-20 mA w/ HART | T22: N/A | U22: N/A | V22: LO | W22: LO | X22: LO | Y22: LO | Z22: N/A | AA22: N/A | AB22: LO | AC22: LO | AD22: N/A | AE22: LO | AF22: LO | AG22: LO | AH22: 23.7 | AI22: Pass | AJ22: N/A | AK22: N/A | AL22: Pass | AM22: Pass | AN22: N/A | AO22: Pass | AP22: N/A | AQ22: N/A | AR22: Pass | AS22: Pass | AT22: N/A | AU22: N/A | AV22: EMERSON | AW22: TREX | AX22: 210100082367 | AY22: '2026-07-31 | CX22: Levy Ostrup | CY22: '2026-08-01
C23: K1B WELL PAD PROJECT | D23: KINOSIS K1B | E23: CA23007 | F23: 29103-PIT-1011 | G23: Pressure Transmitter | H23: STEAM | I23: PAD A S01 HP STM TO INJC WELL TOE | J23: 29103-25J-111-01 | K23: 29103-6"-ST-1102-DASB0-64H | L23: ROSEMOUNT | M23: 3051T | N23: 26SIPG3884776 | O23: 0 - 8000 kPa-g | P23: -101 to 27580 kPa-g | Q23: N/A | R23: YES | S23: 4-20 mA w/ HART | T23: N/A | U23: N/A | V23: LO | W23: LO | X23: LO | Y23: LO | Z23: N/A | AA23: LO | AB23: LO | AC23: LO | AD23: N/A | AE23: LO | AF23: LO | AG23: LO | AH23: 23.4 | AI23: Pass | AJ23: N/A | AK23: N/A | AL23: Pass | AM23: Pass | AN23: N/A | AO23: Pass | AP23: N/A | AQ23: N/A | AR23: Pass | AS23: Pass | AT23: N/A | AU23: N/A | AV23: CRYSTAL ENGINEERING | AW23: IS33-36/5000 PSI | AX23: 4530-525617 | AY23: '2026-07-02 | AZ23: EMERSON | BA23: TREX | BB23: 210100082367 | BC23: '2026-07-31 | CX23: Levy Ostrup | CY23: '2026-08-01
C24: K1B WELL PAD PROJECT | D24: KINOSIS K1B | E24: CA23007 | F24: 29103-PIT-1012 | G24: Pressure Transmitter | H24: STEAM | I24: PAD A S01 HP STM TO INJC WELL HEEL | J24: 29103-25J-111-01 | K24: 29103-4"-ST-1103-DASB0-64H-ET | L24: ROSEMOUNT | M24: 3051T | N24: 26SIPG3884782 | O24: 0 - 8000 kPa-g | P24: -101 - 27580 kPa-g | Q24: N/A | R24: YES | S24: 4-20 mA w/ HART | T24: N/A | U24: N/A | V24: LO | W24: LO | X24: LO | Y24: LO | Z24: N/A | AA24: LO | AB24: LO | AC24: LO | AD24: N/A | AE24: LO | AF24: LO | AG24: LO | AH24: 23.4 | AI24: Pass | AJ24: N/A | AK24: N/A | AL24: Pass | AM24: Pass | AN24: N/A | AO24: Pass | AP24: N/A | AQ24: N/A | AR24: Pass | AS24: Pass | AT24: N/A | AU24: N/A | AV24: CRYSTAL ENGINEERING | AW24: IS33-36/5000 PSI | AX24: 4530-525617 | AY24: '2026-07-02 | AZ24: EMERSON | BA24: TREX | BB24: 210100082367 | BC24: '2026-07-31 | CX24: Levy Ostrup | CY24: '2026-08-01
C25: K1B WELL PAD PROJECT | D25: KINOSIS K1B | E25: CA23007 | F25: 29103-PIT-1021 | G25: Pressure Transmitter | H25: STEAM | I25: PAD A S02 HP STM TO INJC WELL TOE | J25: 29103-25J-121-01 | K25: 29103-6"-ST-1202-DASB0-64H | L25: ROSEMOUNT | M25: 3051T | N25: 26SIPG3884778 | O25: 0 - 8000 kPa-g | P25: -101 - 27580 kPa-g | Q25: N/A | R25: YES | S25: 4-20 mA w/ HART | T25: N/A | U25: N/A | V25: LO | W25: LO | X25: LO | Y25: LO | Z25: N/A | AA25: LO | AB25: LO | AC25: LO | AD25: N/A | AE25: LO | AF25: LO | AG25: LO | AH25: 23.4 | AI25: Pass | AJ25: N/A | AK25: N/A | AL25: Pass | AM25: Pass | AN25: N/A | AO25: Pass | AP25: N/A | AQ25: N/A | AR25: Pass | AS25: Pass | AT25: N/A | AU25: N/A | AV25: CRYSTAL ENGINEERING | AW25: IS33-36/5000 PSI | AX25: 4530-525617 | AY25: '2026-07-02 | AZ25: EMERSON | BA25: TREX | BB25: 210100082367 | BC25: '2026-07-31 | CX25: Levy Ostrup | CY25: '2026-08-01
C26: K1B WELL PAD PROJECT | D26: KINOSIS K1B | E26: CA23007 | F26: 29103-PIT-1022 | G26: Pressure Transmitter | H26: STEAM | I26: PAD A S02 HP STM TO INJC WELL HEEL | J26: 29103-25J-121-01 | K26: 29103-4"-ST-1203-DASB0-64H-ET | L26: ROSEMOUNT | M26: 3051T | N26: 26SIPG3884777 | O26: 0 - 8000 kPa-g | P26: -101 - 27580 kPa-g | Q26: N/A | R26: YES | S26: 4-20 mA w/ HART | T26: N/A | U26: N/A | V26: LO | W26: LO | X26: LO | Y26: LO | Z26: N/A | AA26: LO | AB26: LO | AC26: LO | AD26: N/A | AE26: LO | AF26: LO | AG26: LO | AH26: 23.4 | AI26: Pass | AJ26: N/A | AK26: N/A | AL26: Pass | AM26: Pass | AN26: N/A | AO26: Pass | AP26: N/A | AQ26: N/A | AR26: Pass | AS26: Pass | AT26: N/A | AU26: N/A | AV26: CRYSTAL ENGINEERING | AW26: IS33-36/5000 PSI | AX26: 4530-525617 | AY26: '2026-07-02 | AZ26: EMERSON | BA26: TREX | BB26: 210100082367 | BC26: '2026-07-31 | CX26: Levy Ostrup | CY26: '2026-08-01
C27: K1B WELL PAD PROJECT | D27: KINOSIS K1B | E27: CA23007 | F27: 29103-PIT-1031 | G27: Pressure Transmitter | H27: STEAM | I27: PAD A S03 HP STM TO INJC WELL TOE | J27: 29103-25J-131-01 | K27: 29103-6"-ST-1302-DASB0-64H | L27: ROSEMOUNT | M27: 3051T | N27: 26SIPG3885068 | O27: 0 - 8000 kPa-g | P27: -101 - 27580 kPa-g | Q27: N/A | R27: YES | S27: 4-20 mA w/ HART | T27: N/A | U27: N/A | V27: LO | W27: LO | X27: LO | Y27: LO | Z27: N/A | AA27: LO | AB27: LO | AC27: LO | AD27: N/A | AE27: LO | AF27: LO | AG27: LO | AH27: 23.4 | AI27: Pass | AJ27: N/A | AK27: N/A | AL27: Pass | AM27: Pass | AN27: N/A | AO27: Pass | AP27: N/A | AQ27: N/A | AR27: Pass | AS27: Pass | AT27: N/A | AU27: N/A | AV27: CRYSTAL ENGINEERING | AW27: IS33-36/5000 PSI | AX27: 4530-525617 | AY27: '2026-07-02 | AZ27: EMERSON | BA27: TREX | BB27: 210100082367 | BC27: '2026-07-31 | CX27: Levy Ostrup | CY27: '2026-08-01
C28: K1B WELL PAD PROJECT | D28: KINOSIS K1B | E28: CA23007 | F28: 29103-PIT-1032 | G28: Pressure Transmitter | H28: STEAM | I28: PAD A S03 HP STM TO INJC WELL HEEL | J28: 29103-25J-131-01 | K28: 29103-4"-ST-1303-DASB0-64H-ET | L28: ROSEMOUNT | M28: 3051T | N28: 26SIPG3885067 | O28: 0 - 8000 kPa-g | P28: -101 - 27580 kPa-g | Q28: N/A | R28: YES | S28: 4-20 mA w/ HART | T28: N/A | U28: N/A | V28: LO | W28: LO | X28: LO | Y28: LO | Z28: N/A | AA28: LO | AB28: LO | AC28: LO | AD28: N/A | AE28: LO | AF28: LO | AG28: LO | AH28: 23.4 | AI28: Pass | AJ28: N/A | AK28: N/A | AL28: Pass | AM28: Pass | AN28: N/A | AO28: Pass | AP28: N/A | AQ28: N/A | AR28: Pass | AS28: Pass | AT28: N/A | AU28: N/A | AV28: CRYSTAL ENGINEERING | AW28: IS33-36/5000 PSI | AX28: 4530-525617 | AY28: '2026-07-02 | AZ28: EMERSON | BA28: TREX | BB28: 210100082367 | BC28: '2026-07-31 | CX28: Levy Ostrup | CY28: '2026-08-01
C29: K1B WELL PAD PROJECT | D29: KINOSIS K1B | E29: CA23007 | F29: 29103-PIT-1041 | G29: Pressure Transmitter | H29: STEAM | I29: PAD A S04 HP STM TO INJC WELL TOE | J29: 29103-25J-141-01 | K29: 29103-6"-ST-1402-DASB0-64H | L29: ROSEMOUNT | M29: 3051T | N29: 26SIPG3884596 | O29: 0 - 8000 kPa-g | P29: -101 - 27580 kPa-g | Q29: N/A | R29: YES | S29: 4-20 mA w/ HART | T29: N/A | U29: N/A | V29: LO | W29: LO | X29: LO | Y29: LO | Z29: N/A | AA29: LO | AB29: LO | AC29: LO | AD29: N/A | AE29: LO | AF29: LO | AG29: LO | AH29: 23.4 | AI29: Pass | AJ29: N/A | AK29: N/A | AL29: Pass | AM29: Pass | AN29: N/A | AO29: Pass | AP29: N/A | AQ29: N/A | AR29: Pass | AS29: Pass | AT29: N/A | AU29: N/A | AV29: CRYSTAL ENGINEERING | AW29: IS33-36/5000 PSI | AX29: 4530-525617 | AY29: '2026-07-02 | AZ29: EMERSON | BA29: TREX | BB29: 210100082367 | BC29: '2026-07-31 | CX29: Levy Ostrup | CY29: '2026-08-01
C30: K1B WELL PAD PROJECT | D30: KINOSIS K1B | E30: CA23007 | F30: 29103-PIT-1042 | G30: Pressure Transmitter | H30: STEAM | I30: PAD A S04 HP STM TO INJC WELL HEEL | J30: 29103-25J-141-01 | K30: 29103-6"-ST-1402-DASB0-64H | L30: ROSEMOUNT | M30: 3051T | N30: 26SIPG3884595 | O30: 0 - 8000 kPa-g | P30: -101 - 27580 kPa-g | Q30: N/A | R30: YES | S30: 4-20 mA w/ HART | T30: N/A | U30: N/A | V30: LO | W30: LO | X30: LO | Y30: LO | Z30: N/A | AA30: LO | AB30: LO | AC30: LO | AD30: N/A | AE30: LO | AF30: LO | AG30: LO | AH30: 23.4 | AI30: Pass | AJ30: N/A | AK30: N/A | AL30: Pass | AM30: Pass | AN30: N/A | AO30: Pass | AP30: N/A | AQ30: N/A | AR30: Pass | AS30: Pass | AT30: N/A | AU30: N/A | AV30: CRYSTAL ENGINEERING | AW30: IS33-36/5000 PSI | AX30: 4530-525617 | AY30: '2026-07-02 | AZ30: EMERSON | BA30: TREX | BB30: 210100082367 | BC30: '2026-07-31 | CX30: Levy Ostrup | CY30: '2026-08-01
C31: K1B WELL PAD PROJECT | D31: KINOSIS K1B | E31: CA23007 | F31: 29103-PIT-1051 | G31: Pressure Transmitter | H31: STEAM | I31: PAD A S05 HP STM TO INJC WELL TOE | J31: 29103-25J-151-01 | K31: 29103-6"-ST-1502-DASB0-64H | L31: ROSEMOUNT | M31: 3051T | N31: 26SIPG3884752 | O31: 0 - 8000 kPa-g | P31: -101 - 27580 kPa-g | Q31: N/A | R31: YES | S31: 4-20 mA w/ HART | T31: N/A | U31: N/A | V31: LO | W31: LO | X31: LO | Y31: LO | Z31: N/A | AA31: LO | AB31: LO | AC31: LO | AD31: N/A | AE31: LO | AF31: LO | AG31: LO | AH31: 23.4 | AI31: Pass | AJ31: N/A | AK31: N/A | AL31: Pass | AM31: Pass | AN31: N/A | AO31: Pass | AP31: N/A | AQ31: N/A | AR31: Pass | AS31: Pass | AT31: N/A | AU31: N/A | AV31: CRYSTAL ENGINEERING | AW31: IS33-36/5000 PSI | AX31: 4530-525617 | AY31: '2026-07-02 | AZ31: EMERSON | BA31: TREX | BB31: 210100082367 | BC31: '2026-07-31 | CX31: Levy Ostrup | CY31: '2026-08-01
C32: K1B WELL PAD PROJECT | D32: KINOSIS K1B | E32: CA23007 | F32: 29103-PIT-1052 | G32: Pressure Transmitter | H32: STEAM | I32: PAD A S05 HP STM TO INJC WELL HEEL | J32: 29103-25J-151-01 | K32: 29103-4"-ST-1503-DASB0-64H-ET | L32: ROSEMOUNT | M32: 3051T | N32: 26SIPG3884595 | O32: 0 - 8000 kPa-g | P32: -101 - 27580 kPa-g | Q32: N/A | R32: YES | S32: 4-20 mA w/ HART | T32: N/A | U32: N/A | V32: LO | W32: LO | X32: LO | Y32: LO | Z32: N/A | AA32: LO | AB32: LO | AC32: LO | AD32: N/A | AE32: LO | AF32: LO | AG32: LO | AH32: 23.4 | AI32: Pass | AJ32: N/A | AK32: N/A | AL32: Pass | AM32: Pass | AN32: N/A | AO32: Pass | AP32: N/A | AQ32: N/A | AR32: Pass | AS32: Pass | AT32: N/A | AU32: N/A | AV32: CRYSTAL ENGINEERING | AW32: IS33-36/5000 PSI | AX32: 4530-525617 | AY32: '2026-07-02 | AZ32: EMERSON | BA32: TREX | BB32: 210100082367 | BC32: '2026-07-31 | CX32: Levy Ostrup | CY32: '2026-08-01
C33: K1B WELL PAD PROJECT | D33: KINOSIS K1B | E33: CA23007 | F33: 29103-PIT-1061 | G33: Pressure Transmitter | H33: STEAM | I33: PAD A S06 HP STM TO INJC WELL TOE | J33: 29103-25J-161-01 | K33: 29103-6"-ST-1602-DASB0-64H | L33: ROSEMOUNT | M33: 3051T | N33: 26SIPG3884746 | O33: 0 - 8000 kPa-g | P33: -101 - 27580 kPa-g | Q33: N/A | R33: YES | S33: 4-20 mA w/ HART | T33: N/A | U33: N/A | V33: LO | W33: LO | X33: LO | Y33: LO | Z33: N/A | AA33: LO | AB33: LO | AC33: LO | AD33: N/A | AE33: LO | AF33: LO | AG33: LO | AH33: 23.4 | AI33: Pass | AJ33: N/A | AK33: N/A | AL33: Pass | AM33: Pass | AN33: N/A | AO33: Pass | AP33: N/A | AQ33: N/A | AR33: Pass | AS33: Pass | AT33: N/A | AU33: N/A | AV33: CRYSTAL ENGINEERING | AW33: IS33-36/5000 PSI | AX33: 4530-525617 | AY33: '2026-07-02 | AZ33: EMERSON | BA33: TREX | BB33: 210100082367 | BC33: '2026-07-31 | CX33: Levy Ostrup | CY33: '2026-08-01
C34: K1B WELL PAD PROJECT | D34: KINOSIS K1B | E34: CA23007 | F34: 29103-PIT-1062 | G34: Pressure Transmitter | H34: STEAM | I34: PAD A S06 HP STM TO INJC WELL HEEL | J34: 29103-25J-161-01 | K34: 29103-4"-ST-1603-DASB0-64H-ET | L34: ROSEMOUNT | M34: 3051T | N34: 26SIPG3884742 | O34: 0 - 8000 kPa-g | P34: -101 - 27580 kPa-g | Q34: N/A | R34: YES | S34: 4-20 mA w/ HART | T34: N/A | U34: N/A | V34: LO | W34: LO | X34: LO | Y34: LO | Z34: N/A | AA34: LO | AB34: LO | AC34: LO | AD34: N/A | AE34: LO | AF34: LO | AG34: LO | AH34: 23.4 | AI34: Pass | AJ34: N/A | AK34: N/A | AL34: Pass | AM34: Pass | AN34: N/A | AO34: Pass | AP34: N/A | AQ34: N/A | AR34: Pass | AS34: Pass | AT34: N/A | AU34: N/A | AV34: CRYSTAL ENGINEERING | AW34: IS33-36/5000 PSI | AX34: 4530-525617 | AY34: '2026-07-02 | AZ34: EMERSON | BA34: TREX | BB34: 210100082367 | BC34: '2026-07-31 | CX34: Levy Ostrup | CY34: '2026-08-01
... C38: K1B WELL PAD PROJECT | D38: KINOSIS K1B | E38: CA23007 | F38: 29103-PIT-1018 | G38: Pressure Transmitter | H38: PRODUCED GAS | I38: PAD A P01 PRODUCED VAPOR PRESSURE | J38: 29103-25J-112-01 | K38: 29103-4"-PG-1101-DAPC0-64H-ET | L38: ROSEMOUNT | M38: 3051TG4A2B21AS1M536Q4Q8Q15P1BR5 | N38: 26SIPG3884779 | O38: 0 - 1500 kPa-g | P38: -101 - 5515 kPa-g | Q38: N/A | R38: Yes | S38: 4-20 mA w/ HART | T38: N/A | U38: N/A | V38: LO | W38: LO | X38: LO | Y38: LO | Z38: N/A | AA38: LO | AB38: LO | AC38: LO | AD38: N/A | AE38: LO | AF38: LO | AG38: LO | AH38: 23.9 | AI38: Pass | AJ38: N/A | AK38: N/A | AL38: Pass | AM38: Pass | AN38: N/A | AO38: Pass | AP38: N/A | AQ38: N/A | AR38: Pass | AS38: Pass | AT38: N/A | AU38: N/A | AV38: CRYSTAL ENGINEERING | AW38: IS33-36/5000 PSI | AX38: 4530-525617 | AY38: '2026-07-02 | AZ38: EMERSON | BA38: TREX | BB38: 210100082367 | BC38: '2026-07-31 | CX38: Levy Ostrup | CY38: '2026-08-01
C39: K1B WELL PAD PROJECT | D39: KINOSIS K1B | E39: CA23007 | F39: 29103-TIT-1014 | G39: Temperature Indicating Transmitter | H39: PRODUCED EMULSION | I39: PAD A P01 PRODUCED EMULSION HEAD | J39: 29103-25J-112-01 | K39: 29103-4"-PE-1101-DAPC0-64H-ET | L39: ROSEMOUNT | M39: 3144PD1A1K6M5Q4C8BR5XA | N39: 26SITC3662822 | O39: -50 - 300°C | P39: -200 - 600°C | Q39: N/A | R39: Yes | S39: 4-20 mA w/ HART | T39: N/A | U39: N/A | V39: LO | W39: LO | X39: LO | Y39: LO | Z39: N/A | AA39: N/A | AB39: LO | AC39: LO | AD39: N/A | AE39: LO | AF39: LO | AG39: LO | AH39: 23.2 | AI39: Pass | AJ39: N/A | AK39: N/A | AL39: Pass | AM39: Pass | AN39: N/A | AO39: Pass | AP39: N/A | AQ39: N/A | AR39: Pass | AS39: Pass | AT39: N/A | AU39: N/A | AV39: FLUKE | AW39: 1551A EX | AX39: 6627011 | AY39: '2026-05-13 | CX39: Levy Ostrup | CY39: '2026-08-01
C40: K1B WELL PAD PROJECT | D40: KINOSIS K1B | E40: CA23007 | F40: 29103-PIT-1024 | G40: Pressure Transmitter | H40: PRODUCED EMULSION | I40: PAD A P02 PRODUCED EMULSION PRESSURE | J40: 29103-25J-122-01 | K40: 29103-4"-PE-1201-DAPC0-64H-ET | L40: ROSEMOUNT | M40: 3051TG4A2B21AS1M536Q4Q8Q15P1BR5 | N40: 26SIPG3884604 | O40: 0 - 6000 kPa-g | P40: -101 - 27580 kPa-g | Q40: N/A | R40: Yes | S40: 4-20 mA w/ HART | T40: N/A | U40: N/A | V40: LO | W40: LO | X40: LO | Y40: LO | Z40: N/A | AA40: LO | AB40: LO | AC40: LO | AD40: N/A | AE40: LO | AF40: LO | AG40: LO | AH40: 23.8 | AI40: Pass | AJ40: N/A | AK40: N/A | AL40: Pass | AM40: Pass | AN40: N/A | AO40: Pass | AP40: N/A | AQ40: N/A | AR40: Pass | AS40: Pass | AT40: N/A | AU40: N/A | AV40: CRYSTAL ENGINEERING | AW40: IS33-36/5000 PSI | AX40: 4530-525617 | AY40: '2026-07-02 | AZ40: EMERSON | BA40: TREX | BB40: 210100082367 | BC40: '2026-07-31 | CX40: Levy Ostrup | CY40: '2026-08-01
